<sdf version="1.3">
    <model name="huboplus">
        <link name="Body_Torso">
            <pose>0 0 0 0 -0 0</pose>
            <inertial>
                <pose>0 0 0 0 -0 0</pose>
                <mass>7.50334</mass>
                <inertia>
                    <ixx>0.102019</ixx>
                    <ixy>2.45462e-05</ixy>
                    <ixz>0.00713022</ixz>
                    <iyy>0.0832724</iyy>
                    <iyz>-0.00131733</iyz>
                    <izz>0.086493</izz>
                </inertia>
            </inertial>
            <collision name="Body_Torso_collision">
                <pose>0 0 0 0 -0 0</pose>
                <geometry>
                    <mesh>
                        <scale>1 1 1</scale>
                        <uri>model://huboplus/dae/Body_Torso_col.dae</uri>
                    </mesh>
                </geometry>
            </collision>
            <visual name="Body_Torso_vis">
                <pose>0 0 0 0 -0 0</pose>
                <geometry>
                    <mesh>
                        <scale>1 1 1</scale>
                        <uri>model://huboplus/dae/Body_Torso_vis.dae</uri>
                    </mesh>
                </geometry>
            </visual>
        </link>
        <link name="Body_HNR">
            <pose>0.0122581 0.0024526 0.196935 0 -0 0</pose>
            <inertial>
                <pose>0 0 0 0 -0 0</pose>
                <mass>0.01</mass>
                <inertia>
                    <ixx>0.00164033</ixx>
                    <ixy>-1.08171e-07</ixy>
                    <ixz>-9.53978e-05</ixz>
                    <iyy>0.00153943</iyy>
                    <iyz>1.25376e-06</iyz>
                    <izz>0.00190393</izz>
                </inertia>
            </inertial>
        </link>
        <joint type="revolute" name="HNR">
            <child>Body_HNR</child>
            <parent>Body_Torso</parent>
            <axis>
                <xyz>1 0 0</xyz>
                <limit>
                    <lower>-0.523599</lower>
                    <upper>0.523599</upper>
                </limit>
                <dynamics />
            </axis>
        </joint>
        <link name="Body_HNP">
            <pose>0.0122581 0.0024526 0.196935 0 -0 0</pose>
            <inertial>
                <pose>0.0106886 -3.00864e-05 0.032123 0 -0 0</pose>
                <mass>0.374251</mass>
                <inertia>
                    <ixx>0.00164033</ixx>
                    <ixy>-1.08171e-07</ixy>
                    <ixz>-9.53978e-05</ixz>
                    <iyy>0.00153943</iyy>
                    <iyz>1.25376e-06</iyz>
                    <izz>0.00190393</izz>
                </inertia>
            </inertial>
            <collision name="Body_HNP_collision">
                <pose>0 0 0 0 -0 0</pose>
                <geometry>
                    <mesh>
                        <scale>1 1 1</scale>
                        <uri>model://huboplus/dae/Body_HNP_col.dae</uri>
                    </mesh>
                </geometry>
            </collision>
            <visual name="Body_HNP_vis">
                <pose>0 0 0 0 -0 0</pose>
                <geometry>
                    <mesh>
                        <scale>1 1 1</scale>
                        <uri>model://huboplus/dae/Body_HNP_vis.dae</uri>
                    </mesh>
                </geometry>
            </visual>
        </link>
        <joint type="revolute" name="HNP">
            <child>Body_HNP</child>
            <parent>Body_HNR</parent>
            <axis>
                <xyz>0 1 0</xyz>
                <limit>
                    <lower>-0.523599</lower>
                    <upper>0.523599</upper>
                </limit>
                <dynamics />
            </axis>
        </joint>
        <link name="Body_Hip">
            <pose>0.0122662 0.00245974 -0.15262 0 -0 0</pose>
            <inertial>
                <pose>-0.0138504 7.80652e-06 -0.0354613 0 -0 0</pose>
                <mass>3.41719</mass>
                <inertia>
                    <ixx>0.0180349</ixx>
                    <ixy>3.17531e-05</ixy>
                    <ixz>-0.000513489</ixz>
                    <iyy>0.00912382</iyy>
                    <iyz>-6.90617e-05</iyz>
                    <izz>0.0220514</izz>
                </inertia>
            </inertial>
            <collision name="Body_Hip_collision">
                <pose>0 0 0 0 -0 0</pose>
                <geometry>
                    <mesh>
                        <scale>1 1 1</scale>
                        <uri>model://huboplus/dae/Body_Hip_col.dae</uri>
                    </mesh>
                </geometry>
            </collision>
            <visual name="Body_Hip_vis">
                <pose>0 0 0 0 -0 0</pose>
                <geometry>
                    <mesh>
                        <scale>1 1 1</scale>
                        <uri>model://huboplus/dae/Body_Hip_vis.dae</uri>
                    </mesh>
                </geometry>
            </visual>
        </link>
        <joint type="revolute" name="HPY">
            <child>Body_Hip</child>
            <parent>Body_Torso</parent>
            <axis>
                <xyz>0 0 1</xyz>
                <limit>
                    <lower>-3.14158</lower>
                    <upper>3.14158</upper>
                </limit>
                <dynamics />
            </axis>
        </joint>
        <link name="Body_LHY">
            <pose>0.0123913 0.0909752 -0.229089 0 -0 0</pose>
            <inertial>
                <pose>0.0347065 3.748e-05 -0.0726153 0 -0 0</pose>
                <mass>0.826125</mass>
                <inertia>
                    <ixx>0.00151818</ixx>
                    <ixy>2.13586e-06</ixy>
                    <ixz>0.000434128</ixz>
                    <iyy>0.00286333</iyy>
                    <iyz>-1.57525e-07</iyz>
                    <izz>0.00211437</izz>
                </inertia>
            </inertial>
            <collision name="Body_LHY_collision">
                <pose>0 0 0 0 -0 0</pose>
                <geometry>
                    <mesh>
                        <scale>1 1 1</scale>
                        <uri>model://huboplus/dae/Body_LHY_col.dae</uri>
                    </mesh>
                </geometry>
            </collision>
            <visual name="Body_LHY_vis">
                <pose>0 0 0 0 -0 0</pose>
                <geometry>
                    <mesh>
                        <scale>1 1 1</scale>
                        <uri>model://huboplus/dae/Body_LHY_vis.dae</uri>
                    </mesh>
                </geometry>
            </visual>
        </link>
        <joint type="revolute" name="LHY">
            <child>Body_LHY</child>
            <parent>Body_Hip</parent>
            <axis>
                <xyz>0 0 1</xyz>
                <limit>
                    <lower>-1.5708</lower>
                    <upper>1.5708</upper>
                </limit>
                <dynamics />
            </axis>
        </joint>
        <link name="Body_LHR">
            <pose>0.0643914 0.0909767 -0.320093 0 -0 0</pose>
            <inertial>
                <pose>-0.0497479 0.0125311 -0.0156437 0 -0 0</pose>
                <mass>1.93266</mass>
                <inertia>
                    <ixx>0.00403487</ixx>
                    <ixy>7.9452e-05</ixy>
                    <ixz>-0.000125343</ixz>
                    <iyy>0.00332707</iyy>
                    <iyz>-0.000551964</iyz>
                    <izz>0.00317173</izz>
                </inertia>
            </inertial>
            <collision name="Body_LHR_collision">
                <pose>0 0 0 0 -0 0</pose>
                <geometry>
                    <mesh>
                        <scale>1 1 1</scale>
                        <uri>model://huboplus/dae/Body_LHR_col.dae</uri>
                    </mesh>
                </geometry>
            </collision>
            <visual name="Body_LHR_vis">
                <pose>0 0 0 0 -0 0</pose>
                <geometry>
                    <mesh>
                        <scale>1 1 1</scale>
                        <uri>model://huboplus/dae/Body_LHR_vis.dae</uri>
                    </mesh>
                </geometry>
            </visual>
        </link>
        <joint type="revolute" name="LHR">
            <child>Body_LHR</child>
            <parent>Body_LHY</parent>
            <axis>
                <xyz>1 0 0</xyz>
                <limit>
                    <lower>-0.488692</lower>
                    <upper>0.488692</upper>
                </limit>
                <dynamics />
            </axis>
        </joint>
        <link name="Body_LHP">
            <pose>0.011484 0.156552 -0.319993 0 -0 0</pose>
            <inertial>
                <pose>0.0195049 -0.0595775 -0.175202 0 -0 0</pose>
                <mass>2.8201</mass>
                <inertia>
                    <ixx>0.0295102</ixx>
                    <ixy>0.000184399</ixy>
                    <ixz>-0.000370291</ixz>
                    <iyy>0.0273771</iyy>
                    <iyz>0.00065658</iyz>
                    <izz>0.00838035</izz>
                </inertia>
            </inertial>
            <collision name="Body_LHP_collision">
                <pose>0 0 0 0 -0 0</pose>
                <geometry>
                    <mesh>
                        <scale>1 1 1</scale>
                        <uri>model://huboplus/dae/Body_LHP_col.dae</uri>
                    </mesh>
                </geometry>
            </collision>
            <visual name="Body_LHP_vis">
                <pose>0 0 0 0 -0 0</pose>
                <geometry>
                    <mesh>
                        <scale>1 1 1</scale>
                        <uri>model://huboplus/dae/Body_LHP_vis.dae</uri>
                    </mesh>
                </geometry>
            </visual>
        </link>
        <joint type="revolute" name="LHP">
            <child>Body_LHP</child>
            <parent>Body_LHR</parent>
            <axis>
                <xyz>0 1 0</xyz>
                <limit>
                    <lower>-1.48353</lower>
                    <upper>1.6057</upper>
                </limit>
                <dynamics />
            </axis>
        </joint>
        <link name="Body_LKP">
            <pose>0.0122504 0.11205 -0.6 0 -0 0</pose>
            <inertial>
                <pose>0.0128254 -0.00727567 -0.171431 0 -0 0</pose>
                <mass>1.80912</mass>
                <inertia>
                    <ixx>0.0232156</ixx>
                    <ixy>0.000251648</ixy>
                    <ixz>-0.00129343</ixz>
                    <iyy>0.0208342</iyy>
                    <iyz>0.00278068</iyz>
                    <izz>0.0059204</izz>
                </inertia>
            </inertial>
            <collision name="Body_LKP_collision">
                <pose>0 0 0 0 -0 0</pose>
                <geometry>
                    <mesh>
                        <scale>1 1 1</scale>
                        <uri>model://huboplus/dae/Body_LKP_col.dae</uri>
                    </mesh>
                </geometry>
            </collision>
            <visual name="Body_LKP_vis">
                <pose>0 0 0 0 -0 0</pose>
                <geometry>
                    <mesh>
                        <scale>1 1 1</scale>
                        <uri>model://huboplus/dae/Body_LKP_vis.dae</uri>
                    </mesh>
                </geometry>
            </visual>
        </link>
        <joint type="revolute" name="LKP">
            <child>Body_LKP</child>
            <parent>Body_LHP</parent>
            <axis>
                <xyz>0 1 0</xyz>
                <limit>
                    <lower>-0.0698132</lower>
                    <upper>2.60054</upper>
                </limit>
                <dynamics />
            </axis>
        </joint>
        <link name="Body_LAP">
            <pose>0.0122576 0.136806 -0.879942 0 -0 0</pose>
            <inertial>
                <pose>0.0198702 -0.0459693 0.0115069 0 -0 0</pose>
                <mass>1.63501</mass>
                <inertia>
                    <ixx>0.00231659</ixx>
                    <ixy>1.87402e-05</ixy>
                    <ixz>0.000369899</ixz>
                    <iyy>0.00330411</iyy>
                    <iyz>6.38153e-05</iyz>
                    <izz>0.00279495</izz>
                </inertia>
            </inertial>
            <collision name="Body_LAP_collision">
					<!-- See if this helps -->
          <surface>
            <friction>
              <ode>
                <mu>0.5</mu>
                <mu2>0.5</mu2>
              </ode>
            </friction>
					</surface>	
					<!-- -->	
                <pose>0 0 0 0 -0 0</pose>
                <geometry>
                    <mesh>
                        <scale>1 1 1</scale>
                        <uri>model://huboplus/dae/Body_LAP_col.dae</uri>
                    </mesh>
                </geometry>
            </collision>
            <visual name="Body_LAP_vis">
                <pose>0 0 0 0 -0 0</pose>
                <geometry>
                    <mesh>
                        <scale>1 1 1</scale>
                        <uri>model://huboplus/dae/Body_LAP_vis.dae</uri>
                    </mesh>
                </geometry>
            </visual>
        </link>
        <joint type="revolute" name="LAP">
            <child>Body_LAP</child>
            <parent>Body_LKP</parent>
            <axis>
                <xyz>0 1 0</xyz>
                <limit>
                    <lower>-1.29154</lower>
                    <upper>1.69297</upper>
                </limit>
                <dynamics />
            </axis>
        </joint>
        <link name="Body_LAR">
            <pose>0.0834363 0.0902053 -0.879942 0 -0 0</pose>
            <inertial>
                <pose>-0.0515094 0.00216398 -0.0693881 0 -0 0</pose>
                <mass>1.20318</mass>
                <inertia>
                    <ixx>0.00295183</ixx>
                    <ixy>3.23211e-05</ixy>
                    <ixz>0.000141769</ixz>
                    <iyy>0.00524792</iyy>
                    <iyz>5.95404e-05</iyz>
                    <izz>0.00516817</izz>
                </inertia>
            </inertial>
            <collision name="Body_LAR_collision">
                <pose>0 0 0 0 -0 0</pose>
                <geometry>
                    <mesh>
                        <scale>1 1 1</scale>
                        <uri>model://huboplus/dae/Body_LAR_col.dae</uri>
                    </mesh>
                </geometry>
            </collision>
            <visual name="Body_LAR_vis">
                <pose>0 0 0 0 -0 0</pose>
                <geometry>
                    <mesh>
                        <scale>1 1 1</scale>
                        <uri>model://huboplus/dae/Body_LAR_vis.dae</uri>
                    </mesh>
                </geometry>
            </visual>
        </link>
        <joint type="revolute" name="LAR">
            <child>Body_LAR</child>
            <parent>Body_LAP</parent>
            <axis>
                <xyz>1 0 0</xyz>
                <limit>
                    <lower>-0.191986</lower>
                    <upper>0.191986</upper>
                </limit>
                <dynamics />
            </axis>
        </joint>
        <link name="Body_RHY">
            <pose>0.0123913 -0.0860402 -0.229089 0 -0 0</pose>
            <inertial>
                <pose>0.0347065 -3.748e-05 -0.0726153 0 -0 0</pose>
                <mass>0.826125</mass>
                <inertia>
                    <ixx>0.00151818</ixx>
                    <ixy>-2.13586e-06</ixy>
                    <ixz>0.000434128</ixz>
                    <iyy>0.00286333</iyy>
                    <iyz>1.57525e-07</iyz>
                    <izz>0.00211437</izz>
                </inertia>
            </inertial>
            <collision name="Body_RHY_collision">
                <pose>0 0 0 0 -0 0</pose>
                <geometry>
                    <mesh>
                        <scale>1 1 1</scale>
                        <uri>model://huboplus/dae/Body_RHY_col.dae</uri>
                    </mesh>
                </geometry>
            </collision>
            <visual name="Body_RHY_vis">
                <pose>0 0 0 0 -0 0</pose>
                <geometry>
                    <mesh>
                        <scale>1 1 1</scale>
                        <uri>model://huboplus/dae/Body_RHY_vis.dae</uri>
                    </mesh>
                </geometry>
            </visual>
        </link>
        <joint type="revolute" name="RHY">
            <child>Body_RHY</child>
            <parent>Body_Hip</parent>
            <axis>
                <xyz>0 0 1</xyz>
                <limit>
                    <lower>-1.5708</lower>
                    <upper>1.5708</upper>
                </limit>
                <dynamics />
            </axis>
        </joint>
        <link name="Body_RHR">
            <pose>0.0643914 -0.0859667 -0.320093 0 -0 0</pose>
            <inertial>
                <pose>-0.0497479 -0.0125311 -0.0156437 0 -0 0</pose>
                <mass>1.93266</mass>
                <inertia>
                    <ixx>0.00403487</ixx>
                    <ixy>-7.9452e-05</ixy>
                    <ixz>-0.000125343</ixz>
                    <iyy>0.00332707</iyy>
                    <iyz>0.000551964</iyz>
                    <izz>0.00317173</izz>
                </inertia>
            </inertial>
            <collision name="Body_RHR_collision">
                <pose>0 0 0 0 -0 0</pose>
                <geometry>
                    <mesh>
                        <scale>1 1 1</scale>
                        <uri>model://huboplus/dae/Body_RHR_col.dae</uri>
                    </mesh>
                </geometry>
            </collision>
            <visual name="Body_RHR_vis">
                <pose>0 0 0 0 -0 0</pose>
                <geometry>
                    <mesh>
                        <scale>1 1 1</scale>
                        <uri>model://huboplus/dae/Body_RHR_vis.dae</uri>
                    </mesh>
                </geometry>
            </visual>
        </link>
        <joint type="revolute" name="RHR">
            <child>Body_RHR</child>
            <parent>Body_RHY</parent>
            <axis>
                <xyz>1 0 0</xyz>
                <limit>
                    <lower>-0.488692</lower>
                    <upper>0.488692</upper>
                </limit>
                <dynamics />
            </axis>
        </joint>
        <link name="Body_RHP">
            <pose>0.011484 -0.151542 -0.319993 0 -0 0</pose>
            <inertial>
                <pose>0.0195049 0.0595775 -0.175202 0 -0 0</pose>
                <mass>2.8201</mass>
                <inertia>
                    <ixx>0.0295102</ixx>
                    <ixy>-0.000184399</ixy>
                    <ixz>-0.000370291</ixz>
                    <iyy>0.0273771</iyy>
                    <iyz>-0.00065658</iyz>
                    <izz>0.00838035</izz>
                </inertia>
            </inertial>
            <collision name="Body_RHP_collision">
                <pose>0 0 0 0 -0 0</pose>
                <geometry>
                    <mesh>
                        <scale>1 1 1</scale>
                        <uri>model://huboplus/dae/Body_RHP_col.dae</uri>
                    </mesh>
                </geometry>
            </collision>
            <visual name="Body_RHP_vis">
                <pose>0 0 0 0 -0 0</pose>
                <geometry>
                    <mesh>
                        <scale>1 1 1</scale>
                        <uri>model://huboplus/dae/Body_RHP_vis.dae</uri>
                    </mesh>
                </geometry>
            </visual>
        </link>
        <joint type="revolute" name="RHP">
            <child>Body_RHP</child>
            <parent>Body_RHR</parent>
            <axis>
                <xyz>0 1 0</xyz>
                <limit>
                    <lower>-1.48353</lower>
                    <upper>1.6057</upper>
                </limit>
                <dynamics />
            </axis>
        </joint>
        <link name="Body_RKP">
            <pose>0.0122504 -0.10704 -0.6 0 -0 0</pose>
            <inertial>
                <pose>0.0128254 0.00727567 -0.171431 0 -0 0</pose>
                <mass>1.80912</mass>
                <inertia>
                    <ixx>0.0232156</ixx>
                    <ixy>-0.000251648</ixy>
                    <ixz>-0.00129343</ixz>
                    <iyy>0.0208342</iyy>
                    <iyz>-0.00278068</iyz>
                    <izz>0.0059204</izz>
                </inertia>
            </inertial>
            <collision name="Body_RKP_collision">
                <pose>0 0 0 0 -0 0</pose>
                <geometry>
                    <mesh>
                        <scale>1 1 1</scale>
                        <uri>model://huboplus/dae/Body_RKP_col.dae</uri>
                    </mesh>
                </geometry>
            </collision>
            <visual name="Body_RKP_vis">
                <pose>0 0 0 0 -0 0</pose>
                <geometry>
                    <mesh>
                        <scale>1 1 1</scale>
                        <uri>model://huboplus/dae/Body_RKP_vis.dae</uri>
                    </mesh>
                </geometry>
            </visual>
        </link>
        <joint type="revolute" name="RKP">
            <child>Body_RKP</child>
            <parent>Body_RHP</parent>
            <axis>
                <xyz>0 1 0</xyz>
                <limit>
                    <lower>-0.0698132</lower>
                    <upper>2.60054</upper>
                </limit>
                <dynamics />
            </axis>
        </joint>
        <link name="Body_RAP">
            <pose>0.0122576 -0.131796 -0.879942 0 -0 0</pose>
            <inertial>
                <pose>0.0198702 0.0459693 0.0115069 0 -0 0</pose>
                <mass>1.63501</mass>
                <inertia>
                    <ixx>0.00231659</ixx>
                    <ixy>-1.87402e-05</ixy>
                    <ixz>0.000369899</ixz>
                    <iyy>0.00330411</iyy>
                    <iyz>-6.38153e-05</iyz>
                    <izz>0.00279495</izz>
                </inertia>
            </inertial>
            <collision name="Body_RAP_collision">
                <pose>0 0 0 0 -0 0</pose>
                <geometry>
                    <mesh>
                        <scale>1 1 1</scale>
                        <uri>model://huboplus/dae/Body_RAP_col.dae</uri>
                    </mesh>
                </geometry>
            </collision>
            <visual name="Body_RAP_vis">
                <pose>0 0 0 0 -0 0</pose>
                <geometry>
                    <mesh>
                        <scale>1 1 1</scale>
                        <uri>model://huboplus/dae/Body_RAP_vis.dae</uri>
                    </mesh>
                </geometry>
            </visual>
        </link>
        <joint type="revolute" name="RAP">
            <child>Body_RAP</child>
            <parent>Body_RKP</parent>
            <axis>
                <xyz>0 1 0</xyz>
                <limit>
                    <lower>-1.29154</lower>
                    <upper>1.69297</upper>
                </limit>
                <dynamics />
            </axis>
        </joint>
        <link name="Body_RAR">
            <pose>0.0834363 -0.0851953 -0.879942 0 -0 0</pose>
            <inertial>
                <pose>-0.0515094 -0.00216398 -0.0693881 0 -0 0</pose>
                <mass>1.20318</mass>
                <inertia>
                    <ixx>0.00295183</ixx>
                    <ixy>-3.23211e-05</ixy>
                    <ixz>0.000141769</ixz>
                    <iyy>0.00524792</iyy>
                    <iyz>-5.95404e-05</iyz>
                    <izz>0.00516817</izz>
                </inertia>
            </inertial>
            <collision name="Body_RAR_collision">
                <pose>0 0 0 0 -0 0</pose>
                <geometry>
                    <mesh>
                        <scale>1 1 1</scale>
                        <uri>model://huboplus/dae/Body_RAR_col.dae</uri>
                    </mesh>
                </geometry>
            </collision>
            <visual name="Body_RAR_vis">
                <pose>0 0 0 0 -0 0</pose>
                <geometry>
                    <mesh>
                        <scale>1 1 1</scale>
                        <uri>model://huboplus/dae/Body_RAR_vis.dae</uri>
                    </mesh>
                </geometry>
            </visual>
        </link>
        <joint type="revolute" name="RAR">
            <child>Body_RAR</child>
            <parent>Body_RAP</parent>
            <axis>
                <xyz>1 0 0</xyz>
                <limit>
                    <lower>-0.191986</lower>
                    <upper>0.191986</upper>
                </limit>
                <dynamics />
            </axis>
        </joint>
        <link name="Body_LSP">
            <pose>0.0122581 0.143973 0.0486356 0 -0 0</pose>
            <inertial>
                <pose>0.0167207 0.0570407 9.91873e-06 0 -0 0</pose>
                <mass>0.646655</mass>
                <inertia>
                    <ixx>0.000893731</ixx>
                    <ixy>-0.000156484</ixy>
                    <ixz>4.98007e-07</ixz>
                    <iyy>0.00093016</iyy>
                    <iyz>1.57095e-07</iyz>
                    <izz>0.00124323</izz>
                </inertia>
            </inertial>
            <collision name="Body_LSP_collision">
                <pose>0 0 0 0 -0 0</pose>
                <geometry>
                    <mesh>
                        <scale>1 1 1</scale>
                        <uri>model://huboplus/dae/Body_LSP_col.dae</uri>
                    </mesh>
                </geometry>
            </collision>
            <visual name="Body_LSP_vis">
                <pose>0 0 0 0 -0 0</pose>
                <geometry>
                    <mesh>
                        <scale>1 1 1</scale>
                        <uri>model://huboplus/dae/Body_LSP_vis.dae</uri>
                    </mesh>
                </geometry>
            </visual>
        </link>
        <joint type="revolute" name="LSP">
            <child>Body_LSP</child>
            <parent>Body_Torso</parent>
            <axis>
                <xyz>0 1 0</xyz>
                <limit>
                    <lower>-3.14158</lower>
                    <upper>3.14158</upper>
                </limit>
                <dynamics />
            </axis>
        </joint>
        <link name="Body_LSR">
            <pose>0.0391581 0.215973 0.0486356 0 -0 0</pose>
            <inertial>
                <pose>-0.036208 -8.31243e-05 -0.00126685 0 -0 0</pose>
                <mass>0.413368</mass>
                <inertia>
                    <ixx>0.000269283</ixx>
                    <ixy>4.52571e-07</ixy>
                    <ixz>3.23662e-06</ixz>
                    <iyy>0.00037679</iyy>
                    <iyz>9.93935e-07</iyz>
                    <izz>0.000360355</izz>
                </inertia>
            </inertial>
            <collision name="Body_LSR_collision">
                <pose>0 0 0 0 -0 0</pose>
                <geometry>
                    <mesh>
                        <scale>1 1 1</scale>
                        <uri>model://huboplus/dae/Body_LSR_col.dae</uri>
                    </mesh>
                </geometry>
            </collision>
            <visual name="Body_LSR_vis">
                <pose>0 0 0 0 -0 0</pose>
                <geometry>
                    <mesh>
                        <scale>1 1 1</scale>
                        <uri>model://huboplus/dae/Body_LSR_vis.dae</uri>
                    </mesh>
                </geometry>
            </visual>
        </link>
        <joint type="revolute" name="LSR">
            <child>Body_LSR</child>
            <parent>Body_LSP</parent>
            <axis>
                <xyz>1 0 0</xyz>
                <limit>
                    <lower>-1.5708</lower>
                    <upper>1.5708</upper>
                </limit>
                <dynamics />
            </axis>
        </joint>
        <link name="Body_LSY">
            <pose>0.0122581 0.215807 0.0241356 0 -0 0</pose>
            <inertial>
                <pose>0.00456121 3.10576e-05 -0.0907824 0 -0 0</pose>
                <mass>1.15461</mass>
                <inertia>
                    <ixx>0.00365479</ixx>
                    <ixy>2.05436e-06</ixy>
                    <ixz>0.000418448</ixz>
                    <iyy>0.00364731</iyy>
                    <iyz>-3.09648e-05</iyz>
                    <izz>0.00060633</izz>
                </inertia>
            </inertial>
            <collision name="Body_LSY_collision">
                <pose>0 0 0 0 -0 0</pose>
                <geometry>
                    <mesh>
                        <scale>1 1 1</scale>
                        <uri>model://huboplus/dae/Body_LSY_col.dae</uri>
                    </mesh>
                </geometry>
            </collision>
            <visual name="Body_LSY_vis">
                <pose>0 0 0 0 -0 0</pose>
                <geometry>
                    <mesh>
                        <scale>1 1 1</scale>
                        <uri>model://huboplus/dae/Body_LSY_vis.dae</uri>
                    </mesh>
                </geometry>
            </visual>
        </link>
        <joint type="revolute" name="LSY">
            <child>Body_LSY</child>
            <parent>Body_LSR</parent>
            <axis>
                <xyz>0 0 1</xyz>
                <limit>
                    <lower>-3.14158</lower>
                    <upper>3.14158</upper>
                </limit>
                <dynamics />
            </axis>
        </joint>
        <link name="Body_LEP">
            <pose>0.0342517 0.197807 -0.133369 0 -0 0</pose>
            <inertial>
                <pose>-0.0217349 0.0178314 -0.0610873 0 -0 0</pose>
                <mass>0.44094</mass>
                <inertia>
                    <ixx>0.0005027</ixx>
                    <ixy>3.64587e-06</ixy>
                    <ixz>-1.41388e-05</ixz>
                    <iyy>0.00049415</iyy>
                    <iyz>7.65528e-06</iyz>
                    <izz>0.000131786</izz>
                </inertia>
            </inertial>
            <collision name="Body_LEP_collision">
                <pose>0 0 0 0 -0 0</pose>
                <geometry>
                    <mesh>
                        <scale>1 1 1</scale>
                        <uri>model://huboplus/dae/Body_LEP_col.dae</uri>
                    </mesh>
                </geometry>
            </collision>
            <visual name="Body_LEP_vis">
                <pose>0 0 0 0 -0 0</pose>
                <geometry>
                    <mesh>
                        <scale>1 1 1</scale>
                        <uri>model://huboplus/dae/Body_LEP_vis.dae</uri>
                    </mesh>
                </geometry>
            </visual>
        </link>
        <joint type="revolute" name="LEP">
            <child>Body_LEP</child>
            <parent>Body_LSY</parent>
            <axis>
                <xyz>0 1 0</xyz>
                <limit>
                    <lower>-2.49582</lower>
                    <upper>0.0698132</upper>
                </limit>
                <dynamics />
            </axis>
        </joint>
        <link name="Body_LWY">
            <pose>0.0122611 0.215807 -0.244777 0 -0 0</pose>
            <inertial>
                <pose>-0.00122019 0.000635233 -0.0238043 0 -0 0</pose>
                <mass>0.537738</mass>
                <inertia>
                    <ixx>0.00063457</ixx>
                    <ixy>-4.62486e-07</ixy>
                    <ixz>6.20682e-06</ixz>
                    <iyy>0.000563918</iyy>
                    <iyz>3.54044e-05</iyz>
                    <izz>0.000305422</izz>
                </inertia>
            </inertial>
            <collision name="Body_LWY_collision">
                <pose>0 0 0 0 -0 0</pose>
                <geometry>
                    <mesh>
                        <scale>1 1 1</scale>
                        <uri>model://huboplus/dae/Body_LWY_col.dae</uri>
                    </mesh>
                </geometry>
            </collision>
            <visual name="Body_LWY_vis">
                <pose>0 0 0 0 -0 0</pose>
                <geometry>
                    <mesh>
                        <scale>1 1 1</scale>
                        <uri>model://huboplus/dae/Body_LWY_vis.dae</uri>
                    </mesh>
                </geometry>
            </visual>
        </link>
        <joint type="revolute" name="LWY">
            <child>Body_LWY</child>
            <parent>Body_LEP</parent>
            <axis>
                <xyz>0 0 1</xyz>
                <limit>
                    <lower>-3.14158</lower>
                    <upper>3.14158</upper>
                </limit>
                <dynamics />
            </axis>
        </joint>
        <link name="Body_LWP">
            <pose>0.0122628 0.207077 -0.297327 0 -0 0</pose>
            <inertial>
                <pose>-0.000258199 0.011442 -0.0461472 0 -0 0</pose>
                <mass>0.164393</mass>
                <inertia>
                    <ixx>9.74327e-05</ixx>
                    <ixy>-5.22155e-07</ixy>
                    <ixz>-1.17317e-06</ixz>
                    <iyy>0.000144494</iyy>
                    <iyz>9.4927e-06</iyz>
                    <izz>0.000122681</izz>
                </inertia>
            </inertial>
            <collision name="Body_LWP_collision">
                <pose>0 0 0 0 -0 0</pose>
                <geometry>
                    <mesh>
                        <scale>1 1 1</scale>
                        <uri>model://huboplus/dae/Body_LWP_col.dae</uri>
                    </mesh>
                </geometry>
            </collision>
            <visual name="Body_LWP_vis">
                <pose>0 0 0 0 -0 0</pose>
                <geometry>
                    <mesh>
                        <scale>1 1 1</scale>
                        <uri>model://huboplus/dae/Body_LWP_vis.dae</uri>
                    </mesh>
                </geometry>
            </visual>
        </link>
        <joint type="revolute" name="LWP">
            <child>Body_LWP</child>
            <parent>Body_LWY</parent>
            <axis>
                <xyz>0 1 0</xyz>
                <limit>
                    <lower>-1.64061</lower>
                    <upper>1.01229</upper>
                </limit>
                <dynamics />
            </axis>
        </joint>
        <link name="leftIndexProximal">
            <pose>0.0411787 0.236939 -0.38621 1.5708 0.785398 1.5708</pose>
            <inertial>
                <pose>0.024 0 0 0 -0 0</pose>
                <mass>0.096</mass>
                <inertia>
                    <ixx>2.304e-06</ixx>
                    <ixy>0</ixy>
                    <ixz>0</ixz>
                    <iyy>8.96e-06</iyy>
                    <iyz>6.85949e-15</iyz>
                    <izz>9.216e-06</izz>
                </inertia>
            </inertial>
            <collision name="leftIndexProximal_collision">
                <pose>0 0 0 0 -0 0</pose>
                <geometry>
                    <mesh>
                        <scale>1 1 1</scale>
                        <uri>model://huboplus/dae/leftIndexProximal_vis.dae</uri>
                    </mesh>
                </geometry>
            </collision>
            <visual name="leftIndexProximal_vis">
                <pose>0 0 0 0 -0 0</pose>
                <geometry>
                    <mesh>
                        <scale>1 1 1</scale>
                        <uri>model://huboplus/dae/leftIndexProximal_vis.dae</uri>
                    </mesh>
                </geometry>
            </visual>
        </link>
        <joint type="revolute" name="leftIndexKnuckle1">
            <child>leftIndexProximal</child>
            <parent>Body_LWP</parent>
            <axis>
                <xyz>1 1.07586e-06 -2.59735e-06</xyz>
                <limit>
                    <lower>-3.14</lower>
                    <upper>3.14</upper>
                </limit>
                <dynamics />
            </axis>
        </joint>
        <link name="leftIndexMedial">
            <pose>0.0411786 0.259566 -0.408838 1.5708 0.785398 1.5708</pose>
            <inertial>
                <pose>0.0165 0 0 0 -0 0</pose>
                <mass>0.048</mass>
                <inertia>
                    <ixx>1.152e-06</ixx>
                    <ixy>0</ixy>
                    <ixz>0</ixz>
                    <iyy>2.59e-06</iyy>
                    <iyz>3.42975e-15</iyz>
                    <izz>2.718e-06</izz>
                </inertia>
            </inertial>
            <collision name="leftIndexMedial_collision">
                <pose>0 0 0 0 -0 0</pose>
                <geometry>
                    <mesh>
                        <scale>1 1 1</scale>
                        <uri>model://huboplus/dae/leftIndexMedial_vis.dae</uri>
                    </mesh>
                </geometry>
            </collision>
            <visual name="leftIndexMedial_vis">
                <pose>0 0 0 0 -0 0</pose>
                <geometry>
                    <mesh>
                        <scale>1 1 1</scale>
                        <uri>model://huboplus/dae/leftIndexMedial_vis.dae</uri>
                    </mesh>
                </geometry>
            </visual>
        </link>
        <joint type="revolute" name="Knuckle221">
            <child>leftIndexMedial</child>
            <parent>leftIndexProximal</parent>
            <axis>
                <xyz>-1 -1.07586e-06 2.59735e-06</xyz>
                <limit>
                    <lower>-3.14</lower>
                    <upper>3.14</upper>
                </limit>
                <dynamics />
            </axis>
        </joint>
        <link name="leftIndexDistal">
            <pose>0.0411786 0.275123 -0.424394 1.5708 0.785398 1.5708</pose>
            <inertial>
                <pose>0.015 0 0 0 -0 0</pose>
                <mass>0.08</mass>
                <inertia>
                    <ixx>1.92e-06</ixx>
                    <ixy>0</ixy>
                    <ixz>0</ixz>
                    <iyy>3.82667e-06</iyy>
                    <iyz>5.71624e-15</iyz>
                    <izz>4.04e-06</izz>
                </inertia>
            </inertial>
            <collision name="leftIndexDistal_collision">
                <pose>0 0 0 0 -0 0</pose>
                <geometry>
                    <mesh>
                        <scale>1 1 1</scale>
                        <uri>model://huboplus/dae/leftIndexDistal_vis.dae</uri>
                    </mesh>
                </geometry>
            </collision>
            <visual name="leftIndexDistal_vis">
                <pose>0 0 0 0 -0 0</pose>
                <geometry>
                    <mesh>
                        <scale>1 1 1</scale>
                        <uri>model://huboplus/dae/leftIndexDistal_vis.dae</uri>
                    </mesh>
                </geometry>
            </visual>
        </link>
        <joint type="revolute" name="Knuckle322">
            <child>leftIndexDistal</child>
            <parent>leftIndexMedial</parent>
            <axis>
                <xyz>-1 -1.07586e-06 2.59735e-06</xyz>
                <limit>
                    <lower>-3.14</lower>
                    <upper>3.14</upper>
                </limit>
                <dynamics />
            </axis>
        </joint>
        <link name="leftMiddleProximal">
            <pose>0.0221987 0.236939 -0.38621 1.5708 0.785398 1.5708</pose>
            <inertial>
                <pose>0.024 0 0 0 -0 0</pose>
                <mass>0.096</mass>
                <inertia>
                    <ixx>2.304e-06</ixx>
                    <ixy>0</ixy>
                    <ixz>0</ixz>
                    <iyy>8.96e-06</iyy>
                    <iyz>6.85949e-15</iyz>
                    <izz>9.216e-06</izz>
                </inertia>
            </inertial>
            <collision name="leftMiddleProximal_collision">
                <pose>0 0 0 0 -0 0</pose>
                <geometry>
                    <mesh>
                        <scale>1 1 1</scale>
                        <uri>model://huboplus/dae/leftMiddleProximal_vis.dae</uri>
                    </mesh>
                </geometry>
            </collision>
            <visual name="leftMiddleProximal_vis">
                <pose>0 0 0 0 -0 0</pose>
                <geometry>
                    <mesh>
                        <scale>1 1 1</scale>
                        <uri>model://huboplus/dae/leftMiddleProximal_vis.dae</uri>
                    </mesh>
                </geometry>
            </visual>
        </link>
        <joint type="revolute" name="leftMiddleKnuckle1">
            <child>leftMiddleProximal</child>
            <parent>Body_LWP</parent>
            <axis>
                <xyz>1 1.07586e-06 -2.59735e-06</xyz>
                <limit>
                    <lower>-3.14</lower>
                    <upper>3.14</upper>
                </limit>
                <dynamics />
            </axis>
        </joint>
        <link name="leftMiddleMedial">
            <pose>0.0221986 0.259566 -0.408838 1.5708 0.785398 1.5708</pose>
            <inertial>
                <pose>0.0165 0 0 0 -0 0</pose>
                <mass>0.048</mass>
                <inertia>
                    <ixx>1.152e-06</ixx>
                    <ixy>0</ixy>
                    <ixz>0</ixz>
                    <iyy>2.59e-06</iyy>
                    <iyz>3.42975e-15</iyz>
                    <izz>2.718e-06</izz>
                </inertia>
            </inertial>
            <collision name="leftMiddleMedial_collision">
                <pose>0 0 0 0 -0 0</pose>
                <geometry>
                    <mesh>
                        <scale>1 1 1</scale>
                        <uri>model://huboplus/dae/leftMiddleMedial_vis.dae</uri>
                    </mesh>
                </geometry>
            </collision>
            <visual name="leftMiddleMedial_vis">
                <pose>0 0 0 0 -0 0</pose>
                <geometry>
                    <mesh>
                        <scale>1 1 1</scale>
                        <uri>model://huboplus/dae/leftMiddleMedial_vis.dae</uri>
                    </mesh>
                </geometry>
            </visual>
        </link>
        <joint type="revolute" name="Knuckle218">
            <child>leftMiddleMedial</child>
            <parent>leftMiddleProximal</parent>
            <axis>
                <xyz>-1 -1.07586e-06 2.59735e-06</xyz>
                <limit>
                    <lower>-3.14</lower>
                    <upper>3.14</upper>
                </limit>
                <dynamics />
            </axis>
        </joint>
        <link name="leftMiddleDistal">
            <pose>0.0221985 0.275123 -0.424394 1.5708 0.785398 1.5708</pose>
            <inertial>
                <pose>0.015 0 0 0 -0 0</pose>
                <mass>0.08</mass>
                <inertia>
                    <ixx>1.92e-06</ixx>
                    <ixy>0</ixy>
                    <ixz>0</ixz>
                    <iyy>3.82667e-06</iyy>
                    <iyz>5.71624e-15</iyz>
                    <izz>4.04e-06</izz>
                </inertia>
            </inertial>
            <collision name="leftMiddleDistal_collision">
                <pose>0 0 0 0 -0 0</pose>
                <geometry>
                    <mesh>
                        <scale>1 1 1</scale>
                        <uri>model://huboplus/dae/leftMiddleDistal_vis.dae</uri>
                    </mesh>
                </geometry>
            </collision>
            <visual name="leftMiddleDistal_vis">
                <pose>0 0 0 0 -0 0</pose>
                <geometry>
                    <mesh>
                        <scale>1 1 1</scale>
                        <uri>model://huboplus/dae/leftMiddleDistal_vis.dae</uri>
                    </mesh>
                </geometry>
            </visual>
        </link>
        <joint type="revolute" name="Knuckle319">
            <child>leftMiddleDistal</child>
            <parent>leftMiddleMedial</parent>
            <axis>
                <xyz>-1 -1.07586e-06 2.59735e-06</xyz>
                <limit>
                    <lower>-3.14</lower>
                    <upper>3.14</upper>
                </limit>
                <dynamics />
            </axis>
        </joint>
        <link name="leftPinkyProximal">
            <pose>-0.0158413 0.236939 -0.38621 1.5708 0.785398 1.5708</pose>
            <inertial>
                <pose>0.024 0 0 0 -0 0</pose>
                <mass>0.096</mass>
                <inertia>
                    <ixx>2.304e-06</ixx>
                    <ixy>0</ixy>
                    <ixz>0</ixz>
                    <iyy>8.96e-06</iyy>
                    <iyz>6.85949e-15</iyz>
                    <izz>9.216e-06</izz>
                </inertia>
            </inertial>
            <collision name="leftPinkyProximal_collision">
                <pose>0 0 0 0 -0 0</pose>
                <geometry>
                    <mesh>
                        <scale>1 1 1</scale>
                        <uri>model://huboplus/dae/leftPinkyProximal_vis.dae</uri>
                    </mesh>
                </geometry>
            </collision>
            <visual name="leftPinkyProximal_vis">
                <pose>0 0 0 0 -0 0</pose>
                <geometry>
                    <mesh>
                        <scale>1 1 1</scale>
                        <uri>model://huboplus/dae/leftPinkyProximal_vis.dae</uri>
                    </mesh>
                </geometry>
            </visual>
        </link>
        <joint type="revolute" name="leftPinkyKnuckle1">
            <child>leftPinkyProximal</child>
            <parent>Body_LWP</parent>
            <axis>
                <xyz>1 1.07586e-06 -2.59735e-06</xyz>
                <limit>
                    <lower>-3.14</lower>
                    <upper>3.14</upper>
                </limit>
                <dynamics />
            </axis>
        </joint>
        <link name="leftPinkyMedial">
            <pose>-0.0158414 0.259566 -0.408838 1.5708 0.785398 1.5708</pose>
            <inertial>
                <pose>0.0165 0 0 0 -0 0</pose>
                <mass>0.048</mass>
                <inertia>
                    <ixx>1.152e-06</ixx>
                    <ixy>0</ixy>
                    <ixz>0</ixz>
                    <iyy>2.59e-06</iyy>
                    <iyz>3.42975e-15</iyz>
                    <izz>2.718e-06</izz>
                </inertia>
            </inertial>
            <collision name="leftPinkyMedial_collision">
                <pose>0 0 0 0 -0 0</pose>
                <geometry>
                    <mesh>
                        <scale>1 1 1</scale>
                        <uri>model://huboplus/dae/leftPinkyMedial_vis.dae</uri>
                    </mesh>
                </geometry>
            </collision>
            <visual name="leftPinkyMedial_vis">
                <pose>0 0 0 0 -0 0</pose>
                <geometry>
                    <mesh>
                        <scale>1 1 1</scale>
                        <uri>model://huboplus/dae/leftPinkyMedial_vis.dae</uri>
                    </mesh>
                </geometry>
            </visual>
        </link>
        <joint type="revolute" name="Knuckle212">
            <child>leftPinkyMedial</child>
            <parent>leftPinkyProximal</parent>
            <axis>
                <xyz>-1 -1.07586e-06 2.59735e-06</xyz>
                <limit>
                    <lower>-3.14</lower>
                    <upper>3.14</upper>
                </limit>
                <dynamics />
            </axis>
        </joint>
        <link name="leftPinkyDistal">
            <pose>-0.0158414 0.275123 -0.424394 1.5708 0.785398 1.5708</pose>
            <inertial>
                <pose>0.015 0 0 0 -0 0</pose>
                <mass>0.08</mass>
                <inertia>
                    <ixx>1.92e-06</ixx>
                    <ixy>0</ixy>
                    <ixz>0</ixz>
                    <iyy>3.82667e-06</iyy>
                    <iyz>5.71624e-15</iyz>
                    <izz>4.04e-06</izz>
                </inertia>
            </inertial>
            <collision name="leftPinkyDistal_collision">
                <pose>0 0 0 0 -0 0</pose>
                <geometry>
                    <mesh>
                        <scale>1 1 1</scale>
                        <uri>model://huboplus/dae/leftPinkyDistal_vis.dae</uri>
                    </mesh>
                </geometry>
            </collision>
            <visual name="leftPinkyDistal_vis">
                <pose>0 0 0 0 -0 0</pose>
                <geometry>
                    <mesh>
                        <scale>1 1 1</scale>
                        <uri>model://huboplus/dae/leftPinkyDistal_vis.dae</uri>
                    </mesh>
                </geometry>
            </visual>
        </link>
        <joint type="revolute" name="Knuckle313">
            <child>leftPinkyDistal</child>
            <parent>leftPinkyMedial</parent>
            <axis>
                <xyz>-1 -1.07586e-06 2.59735e-06</xyz>
                <limit>
                    <lower>-3.14</lower>
                    <upper>3.14</upper>
                </limit>
                <dynamics />
            </axis>
        </joint>
        <link name="leftRingProximal">
            <pose>0.00315868 0.236939 -0.38621 1.5708 0.785398 1.5708</pose>
            <inertial>
                <pose>0.024 0 0 0 -0 0</pose>
                <mass>0.096</mass>
                <inertia>
                    <ixx>2.304e-06</ixx>
                    <ixy>0</ixy>
                    <ixz>0</ixz>
                    <iyy>8.96e-06</iyy>
                    <iyz>6.85949e-15</iyz>
                    <izz>9.216e-06</izz>
                </inertia>
            </inertial>
            <collision name="leftRingProximal_collision">
                <pose>0 0 0 0 -0 0</pose>
                <geometry>
                    <mesh>
                        <scale>1 1 1</scale>
                        <uri>model://huboplus/dae/leftRingProximal_vis.dae</uri>
                    </mesh>
                </geometry>
            </collision>
            <visual name="leftRingProximal_vis">
                <pose>0 0 0 0 -0 0</pose>
                <geometry>
                    <mesh>
                        <scale>1 1 1</scale>
                        <uri>model://huboplus/dae/leftRingProximal_vis.dae</uri>
                    </mesh>
                </geometry>
            </visual>
        </link>
        <joint type="revolute" name="leftRingKnuckle1">
            <child>leftRingProximal</child>
            <parent>Body_LWP</parent>
            <axis>
                <xyz>1 1.07586e-06 -2.59735e-06</xyz>
                <limit>
                    <lower>-3.14</lower>
                    <upper>3.14</upper>
                </limit>
                <dynamics />
            </axis>
        </joint>
        <link name="leftRingMedial">
            <pose>0.0031586 0.259566 -0.408838 1.5708 0.785398 1.5708</pose>
            <inertial>
                <pose>0.0165 0 0 0 -0 0</pose>
                <mass>0.048</mass>
                <inertia>
                    <ixx>1.152e-06</ixx>
                    <ixy>0</ixy>
                    <ixz>0</ixz>
                    <iyy>2.59e-06</iyy>
                    <iyz>3.42975e-15</iyz>
                    <izz>2.718e-06</izz>
                </inertia>
            </inertial>
            <collision name="leftRingMedial_collision">
                <pose>0 0 0 0 -0 0</pose>
                <geometry>
                    <mesh>
                        <scale>1 1 1</scale>
                        <uri>model://huboplus/dae/leftRingMedial_vis.dae</uri>
                    </mesh>
                </geometry>
            </collision>
            <visual name="leftRingMedial_vis">
                <pose>0 0 0 0 -0 0</pose>
                <geometry>
                    <mesh>
                        <scale>1 1 1</scale>
                        <uri>model://huboplus/dae/leftRingMedial_vis.dae</uri>
                    </mesh>
                </geometry>
            </visual>
        </link>
        <joint type="revolute" name="Knuckle215">
            <child>leftRingMedial</child>
            <parent>leftRingProximal</parent>
            <axis>
                <xyz>-1 -1.07586e-06 2.59735e-06</xyz>
                <limit>
                    <lower>-3.14</lower>
                    <upper>3.14</upper>
                </limit>
                <dynamics />
            </axis>
        </joint>
        <link name="leftRingDistal">
            <pose>0.00315854 0.275123 -0.424394 1.5708 0.785398 1.5708</pose>
            <inertial>
                <pose>0.015 0 0 0 -0 0</pose>
                <mass>0.08</mass>
                <inertia>
                    <ixx>1.92e-06</ixx>
                    <ixy>0</ixy>
                    <ixz>0</ixz>
                    <iyy>3.82667e-06</iyy>
                    <iyz>5.71624e-15</iyz>
                    <izz>4.04e-06</izz>
                </inertia>
            </inertial>
            <collision name="leftRingDistal_collision">
                <pose>0 0 0 0 -0 0</pose>
                <geometry>
                    <mesh>
                        <scale>1 1 1</scale>
                        <uri>model://huboplus/dae/leftRingDistal_vis.dae</uri>
                    </mesh>
                </geometry>
            </collision>
            <visual name="leftRingDistal_vis">
                <pose>0 0 0 0 -0 0</pose>
                <geometry>
                    <mesh>
                        <scale>1 1 1</scale>
                        <uri>model://huboplus/dae/leftRingDistal_vis.dae</uri>
                    </mesh>
                </geometry>
            </visual>
        </link>
        <joint type="revolute" name="Knuckle316">
            <child>leftRingDistal</child>
            <parent>leftRingMedial</parent>
            <axis>
                <xyz>-1 -1.07586e-06 2.59735e-06</xyz>
                <limit>
                    <lower>-3.14</lower>
                    <upper>3.14</upper>
                </limit>
                <dynamics />
            </axis>
        </joint>
        <link name="leftThumbProximal">
            <pose>0.0331587 0.208998 -0.358279 1.5708 -0.785398 -1.5708</pose>
            <inertial>
                <pose>0.024 0 0 0 -0 0</pose>
                <mass>0.096</mass>
                <inertia>
                    <ixx>2.304e-06</ixx>
                    <ixy>0</ixy>
                    <ixz>0</ixz>
                    <iyy>8.96e-06</iyy>
                    <iyz>6.85949e-15</iyz>
                    <izz>9.216e-06</izz>
                </inertia>
            </inertial>
            <collision name="leftThumbProximal_collision">
                <pose>0 0 0 0 -0 0</pose>
                <geometry>
                    <mesh>
                        <scale>1 1 1</scale>
                        <uri>model://huboplus/dae/leftThumbProximal_vis.dae</uri>
                    </mesh>
                </geometry>
            </collision>
            <visual name="leftThumbProximal_vis">
                <pose>0 0 0 0 -0 0</pose>
                <geometry>
                    <mesh>
                        <scale>1 1 1</scale>
                        <uri>model://huboplus/dae/leftThumbProximal_vis.dae</uri>
                    </mesh>
                </geometry>
            </visual>
        </link>
        <joint type="revolute" name="leftThumbKnuckle1">
            <child>leftThumbProximal</child>
            <parent>Body_LWP</parent>
            <axis>
                <xyz>-1 1.07586e-06 -2.59735e-06</xyz>
                <limit>
                    <lower>-3.14</lower>
                    <upper>3.14</upper>
                </limit>
                <dynamics />
            </axis>
        </joint>
        <link name="leftThumbMedial">
            <pose>0.0331586 0.18637 -0.335652 1.5708 -0.785398 -1.5708</pose>
            <inertial>
                <pose>0.0165 0 0 0 -0 0</pose>
                <mass>0.048</mass>
                <inertia>
                    <ixx>1.152e-06</ixx>
                    <ixy>0</ixy>
                    <ixz>0</ixz>
                    <iyy>2.59e-06</iyy>
                    <iyz>3.42975e-15</iyz>
                    <izz>2.718e-06</izz>
                </inertia>
            </inertial>
            <collision name="leftThumbMedial_collision">
                <pose>0 0 0 0 -0 0</pose>
                <geometry>
                    <mesh>
                        <scale>1 1 1</scale>
                        <uri>model://huboplus/dae/leftThumbMedial_vis.dae</uri>
                    </mesh>
                </geometry>
            </collision>
            <visual name="leftThumbMedial_vis">
                <pose>0 0 0 0 -0 0</pose>
                <geometry>
                    <mesh>
                        <scale>1 1 1</scale>
                        <uri>model://huboplus/dae/leftThumbMedial_vis.dae</uri>
                    </mesh>
                </geometry>
            </visual>
        </link>
        <joint type="revolute" name="Knuckle29">
            <child>leftThumbMedial</child>
            <parent>leftThumbProximal</parent>
            <axis>
                <xyz>1 -1.07586e-06 2.59735e-06</xyz>
                <limit>
                    <lower>-3.14</lower>
                    <upper>3.14</upper>
                </limit>
                <dynamics />
            </axis>
        </joint>
        <link name="leftThumbDistal">
            <pose>0.0331586 0.170814 -0.320096 1.5708 -0.785398 -1.5708</pose>
            <inertial>
                <pose>0.015 0 0 0 -0 0</pose>
                <mass>0.08</mass>
                <inertia>
                    <ixx>1.92e-06</ixx>
                    <ixy>0</ixy>
                    <ixz>0</ixz>
                    <iyy>3.82667e-06</iyy>
                    <iyz>5.71624e-15</iyz>
                    <izz>4.04e-06</izz>
                </inertia>
            </inertial>
            <collision name="leftThumbDistal_collision">
                <pose>0 0 0 0 -0 0</pose>
                <geometry>
                    <mesh>
                        <scale>1 1 1</scale>
                        <uri>model://huboplus/dae/leftThumbDistal_vis.dae</uri>
                    </mesh>
                </geometry>
            </collision>
            <visual name="leftThumbDistal_vis">
                <pose>0 0 0 0 -0 0</pose>
                <geometry>
                    <mesh>
                        <scale>1 1 1</scale>
                        <uri>model://huboplus/dae/leftThumbDistal_vis.dae</uri>
                    </mesh>
                </geometry>
            </visual>
        </link>
        <joint type="revolute" name="Knuckle310">
            <child>leftThumbDistal</child>
            <parent>leftThumbMedial</parent>
            <axis>
                <xyz>1 -1.07586e-06 2.59735e-06</xyz>
                <limit>
                    <lower>-3.14</lower>
                    <upper>3.14</upper>
                </limit>
                <dynamics />
            </axis>
        </joint>
        <link name="Body_RSP">
            <pose>0.0122581 -0.139027 0.0486356 0 -0 0</pose>
            <inertial>
                <pose>0.0167207 -0.0570407 9.91873e-06 0 -0 0</pose>
                <mass>0.646655</mass>
                <inertia>
                    <ixx>0.000893731</ixx>
                    <ixy>0.000156484</ixy>
                    <ixz>4.98007e-07</ixz>
                    <iyy>0.00093016</iyy>
                    <iyz>-1.57095e-07</iyz>
                    <izz>0.00124323</izz>
                </inertia>
            </inertial>
            <collision name="Body_RSP_collision">
                <pose>0 0 0 0 -0 0</pose>
                <geometry>
                    <mesh>
                        <scale>1 1 1</scale>
                        <uri>model://huboplus/dae/Body_RSP_col.dae</uri>
                    </mesh>
                </geometry>
            </collision>
            <visual name="Body_RSP_vis">
                <pose>0 0 0 0 -0 0</pose>
                <geometry>
                    <mesh>
                        <scale>1 1 1</scale>
                        <uri>model://huboplus/dae/Body_RSP_vis.dae</uri>
                    </mesh>
                </geometry>
            </visual>
        </link>
        <joint type="revolute" name="RSP">
            <child>Body_RSP</child>
            <parent>Body_Torso</parent>
            <axis>
                <xyz>0 1 0</xyz>
                <limit>
                    <lower>-3.14158</lower>
                    <upper>3.14158</upper>
                </limit>
                <dynamics />
            </axis>
        </joint>
        <link name="Body_RSR">
            <pose>0.0391581 -0.211027 0.0486356 0 -0 0</pose>
            <inertial>
                <pose>-0.036208 8.31243e-05 -0.00126685 0 -0 0</pose>
                <mass>0.413368</mass>
                <inertia>
                    <ixx>0.000269283</ixx>
                    <ixy>-4.52571e-07</ixy>
                    <ixz>3.23662e-06</ixz>
                    <iyy>0.00037679</iyy>
                    <iyz>-9.93935e-07</iyz>
                    <izz>0.000360355</izz>
                </inertia>
            </inertial>
            <collision name="Body_RSR_collision">
                <pose>0 0 0 0 -0 0</pose>
                <geometry>
                    <mesh>
                        <scale>1 1 1</scale>
                        <uri>model://huboplus/dae/Body_RSR_col.dae</uri>
                    </mesh>
                </geometry>
            </collision>
            <visual name="Body_RSR_vis">
                <pose>0 0 0 0 -0 0</pose>
                <geometry>
                    <mesh>
                        <scale>1 1 1</scale>
                        <uri>model://huboplus/dae/Body_RSR_vis.dae</uri>
                    </mesh>
                </geometry>
            </visual>
        </link>
        <joint type="revolute" name="RSR">
            <child>Body_RSR</child>
            <parent>Body_RSP</parent>
            <axis>
                <xyz>1 0 0</xyz>
                <limit>
                    <lower>-1.5708</lower>
                    <upper>1.5708</upper>
                </limit>
                <dynamics />
            </axis>
        </joint>
        <link name="Body_RSY">
            <pose>0.0122581 -0.211027 0.0241356 0 -0 0</pose>
            <inertial>
                <pose>0.00456121 -3.10576e-05 -0.0907824 0 -0 0</pose>
                <mass>1.15461</mass>
                <inertia>
                    <ixx>0.00365479</ixx>
                    <ixy>-2.05436e-06</ixy>
                    <ixz>0.000418448</ixz>
                    <iyy>0.00364731</iyy>
                    <iyz>3.09648e-05</iyz>
                    <izz>0.00060633</izz>
                </inertia>
            </inertial>
            <collision name="Body_RSY_collision">
                <pose>0 0 0 0 -0 0</pose>
                <geometry>
                    <mesh>
                        <scale>1 1 1</scale>
                        <uri>model://huboplus/dae/Body_RSY_col.dae</uri>
                    </mesh>
                </geometry>
            </collision>
            <visual name="Body_RSY_vis">
                <pose>0 0 0 0 -0 0</pose>
                <geometry>
                    <mesh>
                        <scale>1 1 1</scale>
                        <uri>model://huboplus/dae/Body_RSY_vis.dae</uri>
                    </mesh>
                </geometry>
            </visual>
        </link>
        <joint type="revolute" name="RSY">
            <child>Body_RSY</child>
            <parent>Body_RSR</parent>
            <axis>
                <xyz>0 0 1</xyz>
                <limit>
                    <lower>-3.14158</lower>
                    <upper>3.14158</upper>
                </limit>
                <dynamics />
            </axis>
        </joint>
        <link name="Body_REP">
            <pose>0.0342517 -0.193027 -0.133369 0 -0 0</pose>
            <inertial>
                <pose>-0.0217349 -0.0178314 -0.0610873 0 -0 0</pose>
                <mass>0.44094</mass>
                <inertia>
                    <ixx>0.0005027</ixx>
                    <ixy>-3.64587e-06</ixy>
                    <ixz>-1.41388e-05</ixz>
                    <iyy>0.00049415</iyy>
                    <iyz>-7.65528e-06</iyz>
                    <izz>0.000131786</izz>
                </inertia>
            </inertial>
            <collision name="Body_REP_collision">
                <pose>0 0 0 0 -0 0</pose>
                <geometry>
                    <mesh>
                        <scale>1 1 1</scale>
                        <uri>model://huboplus/dae/Body_REP_col.dae</uri>
                    </mesh>
                </geometry>
            </collision>
            <visual name="Body_REP_vis">
                <pose>0 0 0 0 -0 0</pose>
                <geometry>
                    <mesh>
                        <scale>1 1 1</scale>
                        <uri>model://huboplus/dae/Body_REP_vis.dae</uri>
                    </mesh>
                </geometry>
            </visual>
        </link>
        <joint type="revolute" name="REP">
            <child>Body_REP</child>
            <parent>Body_RSY</parent>
            <axis>
                <xyz>0 1 0</xyz>
                <limit>
                    <lower>-2.49582</lower>
                    <upper>0.0698132</upper>
                </limit>
                <dynamics />
            </axis>
        </joint>
        <link name="Body_RWY">
            <pose>0.0122611 -0.211027 -0.244777 0 -0 0</pose>
            <inertial>
                <pose>-0.00122019 -0.000635233 -0.0238043 0 -0 0</pose>
                <mass>0.537738</mass>
                <inertia>
                    <ixx>0.00063457</ixx>
                    <ixy>4.62486e-07</ixy>
                    <ixz>6.20682e-06</ixz>
                    <iyy>0.000563918</iyy>
                    <iyz>-3.54044e-05</iyz>
                    <izz>0.000305422</izz>
                </inertia>
            </inertial>
            <collision name="Body_RWY_collision">
                <pose>0 0 0 0 -0 0</pose>
                <geometry>
                    <mesh>
                        <scale>1 1 1</scale>
                        <uri>model://huboplus/dae/Body_RWY_col.dae</uri>
                    </mesh>
                </geometry>
            </collision>
            <visual name="Body_RWY_vis">
                <pose>0 0 0 0 -0 0</pose>
                <geometry>
                    <mesh>
                        <scale>1 1 1</scale>
                        <uri>model://huboplus/dae/Body_RWY_vis.dae</uri>
                    </mesh>
                </geometry>
            </visual>
        </link>
        <joint type="revolute" name="RWY">
            <child>Body_RWY</child>
            <parent>Body_REP</parent>
            <axis>
                <xyz>0 0 1</xyz>
                <limit>
                    <lower>-3.14158</lower>
                    <upper>3.14158</upper>
                </limit>
                <dynamics />
            </axis>
        </joint>
        <link name="Body_RWP">
            <pose>0.0122628 -0.201027 -0.297327 0 -0 0</pose>
            <inertial>
                <pose>-0.000258199 -0.011442 -0.0461472 0 -0 0</pose>
                <mass>0.164393</mass>
                <inertia>
                    <ixx>9.74327e-05</ixx>
                    <ixy>5.22155e-07</ixy>
                    <ixz>-1.17317e-06</ixz>
                    <iyy>0.000144494</iyy>
                    <iyz>-9.4927e-06</iyz>
                    <izz>0.000122681</izz>
                </inertia>
            </inertial>
            <collision name="Body_RWP_collision">
                <pose>0 0 0 0 -0 0</pose>
                <geometry>
                    <mesh>
                        <scale>1 1 1</scale>
                        <uri>model://huboplus/dae/Body_RWP_col.dae</uri>
                    </mesh>
                </geometry>
            </collision>
            <visual name="Body_RWP_vis">
                <pose>0 0 0 0 -0 0</pose>
                <geometry>
                    <mesh>
                        <scale>1 1 1</scale>
                        <uri>model://huboplus/dae/Body_RWP_vis.dae</uri>
                    </mesh>
                </geometry>
            </visual>
        </link>
        <joint type="revolute" name="RWP">
            <child>Body_RWP</child>
            <parent>Body_RWY</parent>
            <axis>
                <xyz>0 1 0</xyz>
                <limit>
                    <lower>-1.64061</lower>
                    <upper>1.01229</upper>
                </limit>
                <dynamics />
            </axis>
        </joint>
        <link name="rightIndexProximal">
            <pose>0.0411787 -0.230889 -0.38621 1.5708 0.785398 -1.5708</pose>
            <inertial>
                <pose>0.024 0 0 0 -0 0</pose>
                <mass>0.096</mass>
                <inertia>
                    <ixx>2.304e-06</ixx>
                    <ixy>0</ixy>
                    <ixz>0</ixz>
                    <iyy>8.96e-06</iyy>
                    <iyz>6.85949e-15</iyz>
                    <izz>9.216e-06</izz>
                </inertia>
            </inertial>
            <collision name="rightIndexProximal_collision">
                <pose>0 0 0 0 -0 0</pose>
                <geometry>
                    <mesh>
                        <scale>1 1 1</scale>
                        <uri>model://huboplus/dae/rightIndexProximal_vis.dae</uri>
                    </mesh>
                </geometry>
            </collision>
            <visual name="rightIndexProximal_vis">
                <pose>0 0 0 0 -0 0</pose>
                <geometry>
                    <mesh>
                        <scale>1 1 1</scale>
                        <uri>model://huboplus/dae/rightIndexProximal_vis.dae</uri>
                    </mesh>
                </geometry>
            </visual>
        </link>
        <joint type="revolute" name="rightIndexKnuckle1">
            <child>rightIndexProximal</child>
            <parent>Body_RWP</parent>
            <axis>
                <xyz>-1 6.27055e-06 -2.59735e-06</xyz>
                <limit>
                    <lower>-3.14</lower>
                    <upper>3.14</upper>
                </limit>
                <dynamics />
            </axis>
        </joint>
        <link name="rightIndexMedial">
            <pose>0.0411786 -0.253516 -0.408838 1.5708 0.785398 -1.5708</pose>
            <inertial>
                <pose>0.0165 0 0 0 -0 0</pose>
                <mass>0.048</mass>
                <inertia>
                    <ixx>1.152e-06</ixx>
                    <ixy>0</ixy>
                    <ixz>0</ixz>
                    <iyy>2.59e-06</iyy>
                    <iyz>3.42975e-15</iyz>
                    <izz>2.718e-06</izz>
                </inertia>
            </inertial>
            <collision name="rightIndexMedial_collision">
                <pose>0 0 0 0 -0 0</pose>
                <geometry>
                    <mesh>
                        <scale>1 1 1</scale>
                        <uri>model://huboplus/dae/rightIndexMedial_vis.dae</uri>
                    </mesh>
                </geometry>
            </collision>
            <visual name="rightIndexMedial_vis">
                <pose>0 0 0 0 -0 0</pose>
                <geometry>
                    <mesh>
                        <scale>1 1 1</scale>
                        <uri>model://huboplus/dae/rightIndexMedial_vis.dae</uri>
                    </mesh>
                </geometry>
            </visual>
        </link>
        <joint type="revolute" name="Knuckle2">
            <child>rightIndexMedial</child>
            <parent>rightIndexProximal</parent>
            <axis>
                <xyz>1 -6.27055e-06 2.59735e-06</xyz>
                <limit>
                    <lower>-3.14</lower>
                    <upper>3.14</upper>
                </limit>
                <dynamics />
            </axis>
        </joint>
        <link name="rightIndexDistal">
            <pose>0.0411786 -0.269072 -0.424394 1.5708 0.785398 -1.5708</pose>
            <inertial>
                <pose>0.015 0 0 0 -0 0</pose>
                <mass>0.08</mass>
                <inertia>
                    <ixx>1.92e-06</ixx>
                    <ixy>0</ixy>
                    <ixz>0</ixz>
                    <iyy>3.82667e-06</iyy>
                    <iyz>5.71624e-15</iyz>
                    <izz>4.04e-06</izz>
                </inertia>
            </inertial>
            <collision name="rightIndexDistal_collision">
                <pose>0 0 0 0 -0 0</pose>
                <geometry>
                    <mesh>
                        <scale>1 1 1</scale>
                        <uri>model://huboplus/dae/rightIndexDistal_vis.dae</uri>
                    </mesh>
                </geometry>
            </collision>
            <visual name="rightIndexDistal_vis">
                <pose>0 0 0 0 -0 0</pose>
                <geometry>
                    <mesh>
                        <scale>1 1 1</scale>
                        <uri>model://huboplus/dae/rightIndexDistal_vis.dae</uri>
                    </mesh>
                </geometry>
            </visual>
        </link>
        <joint type="revolute" name="Knuckle3">
            <child>rightIndexDistal</child>
            <parent>rightIndexMedial</parent>
            <axis>
                <xyz>1 -6.27055e-06 2.59735e-06</xyz>
                <limit>
                    <lower>-3.14</lower>
                    <upper>3.14</upper>
                </limit>
                <dynamics />
            </axis>
        </joint>
        <link name="rightMiddleProximal">
            <pose>0.0221987 -0.230889 -0.38621 1.5708 0.785398 -1.5708</pose>
            <inertial>
                <pose>0.024 0 0 0 -0 0</pose>
                <mass>0.096</mass>
                <inertia>
                    <ixx>2.304e-06</ixx>
                    <ixy>0</ixy>
                    <ixz>0</ixz>
                    <iyy>8.96e-06</iyy>
                    <iyz>6.85949e-15</iyz>
                    <izz>9.216e-06</izz>
                </inertia>
            </inertial>
            <collision name="rightMiddleProximal_collision">
                <pose>0 0 0 0 -0 0</pose>
                <geometry>
                    <mesh>
                        <scale>1 1 1</scale>
                        <uri>model://huboplus/dae/rightMiddleProximal_vis.dae</uri>
                    </mesh>
                </geometry>
            </collision>
            <visual name="rightMiddleProximal_vis">
                <pose>0 0 0 0 -0 0</pose>
                <geometry>
                    <mesh>
                        <scale>1 1 1</scale>
                        <uri>model://huboplus/dae/rightMiddleProximal_vis.dae</uri>
                    </mesh>
                </geometry>
            </visual>
        </link>
        <joint type="revolute" name="rightMiddleKnuckle1">
            <child>rightMiddleProximal</child>
            <parent>Body_RWP</parent>
            <axis>
                <xyz>-1 6.27055e-06 -2.59735e-06</xyz>
                <limit>
                    <lower>-3.14</lower>
                    <upper>3.14</upper>
                </limit>
                <dynamics />
            </axis>
        </joint>
        <link name="rightMiddleMedial">
            <pose>0.0221986 -0.253516 -0.408838 1.5708 0.785398 -1.5708</pose>
            <inertial>
                <pose>0.0165 0 0 0 -0 0</pose>
                <mass>0.048</mass>
                <inertia>
                    <ixx>1.152e-06</ixx>
                    <ixy>0</ixy>
                    <ixz>0</ixz>
                    <iyy>2.59e-06</iyy>
                    <iyz>3.42975e-15</iyz>
                    <izz>2.718e-06</izz>
                </inertia>
            </inertial>
            <collision name="rightMiddleMedial_collision">
                <pose>0 0 0 0 -0 0</pose>
                <geometry>
                    <mesh>
                        <scale>1 1 1</scale>
                        <uri>model://huboplus/dae/rightMiddleMedial_vis.dae</uri>
                    </mesh>
                </geometry>
            </collision>
            <visual name="rightMiddleMedial_vis">
                <pose>0 0 0 0 -0 0</pose>
                <geometry>
                    <mesh>
                        <scale>1 1 1</scale>
                        <uri>model://huboplus/dae/rightMiddleMedial_vis.dae</uri>
                    </mesh>
                </geometry>
            </visual>
        </link>
        <joint type="revolute" name="Knuckle239">
            <child>rightMiddleMedial</child>
            <parent>rightMiddleProximal</parent>
            <axis>
                <xyz>1 -6.27055e-06 2.59735e-06</xyz>
                <limit>
                    <lower>-3.14</lower>
                    <upper>3.14</upper>
                </limit>
                <dynamics />
            </axis>
        </joint>
        <link name="rightMiddleDistal">
            <pose>0.0221985 -0.269072 -0.424394 1.5708 0.785398 -1.5708</pose>
            <inertial>
                <pose>0.015 0 0 0 -0 0</pose>
                <mass>0.08</mass>
                <inertia>
                    <ixx>1.92e-06</ixx>
                    <ixy>0</ixy>
                    <ixz>0</ixz>
                    <iyy>3.82667e-06</iyy>
                    <iyz>5.71624e-15</iyz>
                    <izz>4.04e-06</izz>
                </inertia>
            </inertial>
            <collision name="rightMiddleDistal_collision">
                <pose>0 0 0 0 -0 0</pose>
                <geometry>
                    <mesh>
                        <scale>1 1 1</scale>
                        <uri>model://huboplus/dae/rightMiddleDistal_vis.dae</uri>
                    </mesh>
                </geometry>
            </collision>
            <visual name="rightMiddleDistal_vis">
                <pose>0 0 0 0 -0 0</pose>
                <geometry>
                    <mesh>
                        <scale>1 1 1</scale>
                        <uri>model://huboplus/dae/rightMiddleDistal_vis.dae</uri>
                    </mesh>
                </geometry>
            </visual>
        </link>
        <joint type="revolute" name="Knuckle340">
            <child>rightMiddleDistal</child>
            <parent>rightMiddleMedial</parent>
            <axis>
                <xyz>1 -6.27055e-06 2.59735e-06</xyz>
                <limit>
                    <lower>-3.14</lower>
                    <upper>3.14</upper>
                </limit>
                <dynamics />
            </axis>
        </joint>
        <link name="rightPinkyProximal">
            <pose>-0.0158413 -0.230889 -0.38621 1.5708 0.785398 -1.5708</pose>
            <inertial>
                <pose>0.024 0 0 0 -0 0</pose>
                <mass>0.096</mass>
                <inertia>
                    <ixx>2.304e-06</ixx>
                    <ixy>0</ixy>
                    <ixz>0</ixz>
                    <iyy>8.96e-06</iyy>
                    <iyz>6.85949e-15</iyz>
                    <izz>9.216e-06</izz>
                </inertia>
            </inertial>
            <collision name="rightPinkyProximal_collision">
                <pose>0 0 0 0 -0 0</pose>
                <geometry>
                    <mesh>
                        <scale>1 1 1</scale>
                        <uri>model://huboplus/dae/rightPinkyProximal_vis.dae</uri>
                    </mesh>
                </geometry>
            </collision>
            <visual name="rightPinkyProximal_vis">
                <pose>0 0 0 0 -0 0</pose>
                <geometry>
                    <mesh>
                        <scale>1 1 1</scale>
                        <uri>model://huboplus/dae/rightPinkyProximal_vis.dae</uri>
                    </mesh>
                </geometry>
            </visual>
        </link>
        <joint type="revolute" name="rightPinkyKnuckle1">
            <child>rightPinkyProximal</child>
            <parent>Body_RWP</parent>
            <axis>
                <xyz>-1 6.27055e-06 -2.59735e-06</xyz>
                <limit>
                    <lower>-3.14</lower>
                    <upper>3.14</upper>
                </limit>
                <dynamics />
            </axis>
        </joint>
        <link name="rightPinkyMedial">
            <pose>-0.0158414 -0.253516 -0.408838 1.5708 0.785398 -1.5708</pose>
            <inertial>
                <pose>0.0165 0 0 0 -0 0</pose>
                <mass>0.048</mass>
                <inertia>
                    <ixx>1.152e-06</ixx>
                    <ixy>0</ixy>
                    <ixz>0</ixz>
                    <iyy>2.59e-06</iyy>
                    <iyz>3.42975e-15</iyz>
                    <izz>2.718e-06</izz>
                </inertia>
            </inertial>
            <collision name="rightPinkyMedial_collision">
                <pose>0 0 0 0 -0 0</pose>
                <geometry>
                    <mesh>
                        <scale>1 1 1</scale>
                        <uri>model://huboplus/dae/rightPinkyMedial_vis.dae</uri>
                    </mesh>
                </geometry>
            </collision>
            <visual name="rightPinkyMedial_vis">
                <pose>0 0 0 0 -0 0</pose>
                <geometry>
                    <mesh>
                        <scale>1 1 1</scale>
                        <uri>model://huboplus/dae/rightPinkyMedial_vis.dae</uri>
                    </mesh>
                </geometry>
            </visual>
        </link>
        <joint type="revolute" name="Knuckle233">
            <child>rightPinkyMedial</child>
            <parent>rightPinkyProximal</parent>
            <axis>
                <xyz>1 -6.27055e-06 2.59735e-06</xyz>
                <limit>
                    <lower>-3.14</lower>
                    <upper>3.14</upper>
                </limit>
                <dynamics />
            </axis>
        </joint>
        <link name="rightPinkyDistal">
            <pose>-0.0158414 -0.269072 -0.424394 1.5708 0.785398 -1.5708</pose>
            <inertial>
                <pose>0.015 0 0 0 -0 0</pose>
                <mass>0.08</mass>
                <inertia>
                    <ixx>1.92e-06</ixx>
                    <ixy>0</ixy>
                    <ixz>0</ixz>
                    <iyy>3.82667e-06</iyy>
                    <iyz>5.71624e-15</iyz>
                    <izz>4.04e-06</izz>
                </inertia>
            </inertial>
            <collision name="rightPinkyDistal_collision">
                <pose>0 0 0 0 -0 0</pose>
                <geometry>
                    <mesh>
                        <scale>1 1 1</scale>
                        <uri>model://huboplus/dae/rightPinkyDistal_vis.dae</uri>
                    </mesh>
                </geometry>
            </collision>
            <visual name="rightPinkyDistal_vis">
                <pose>0 0 0 0 -0 0</pose>
                <geometry>
                    <mesh>
                        <scale>1 1 1</scale>
                        <uri>model://huboplus/dae/rightPinkyDistal_vis.dae</uri>
                    </mesh>
                </geometry>
            </visual>
        </link>
        <joint type="revolute" name="Knuckle334">
            <child>rightPinkyDistal</child>
            <parent>rightPinkyMedial</parent>
            <axis>
                <xyz>1 -6.27055e-06 2.59735e-06</xyz>
                <limit>
                    <lower>-3.14</lower>
                    <upper>3.14</upper>
                </limit>
                <dynamics />
            </axis>
        </joint>
        <link name="rightRingProximal">
            <pose>0.00315868 -0.230889 -0.38621 1.5708 0.785398 -1.5708</pose>
            <inertial>
                <pose>0.024 0 0 0 -0 0</pose>
                <mass>0.096</mass>
                <inertia>
                    <ixx>2.304e-06</ixx>
                    <ixy>0</ixy>
                    <ixz>0</ixz>
                    <iyy>8.96e-06</iyy>
                    <iyz>6.85949e-15</iyz>
                    <izz>9.216e-06</izz>
                </inertia>
            </inertial>
            <collision name="rightRingProximal_collision">
                <pose>0 0 0 0 -0 0</pose>
                <geometry>
                    <mesh>
                        <scale>1 1 1</scale>
                        <uri>model://huboplus/dae/rightRingProximal_vis.dae</uri>
                    </mesh>
                </geometry>
            </collision>
            <visual name="rightRingProximal_vis">
                <pose>0 0 0 0 -0 0</pose>
                <geometry>
                    <mesh>
                        <scale>1 1 1</scale>
                        <uri>model://huboplus/dae/rightRingProximal_vis.dae</uri>
                    </mesh>
                </geometry>
            </visual>
        </link>
        <joint type="revolute" name="rightRingKnuckle1">
            <child>rightRingProximal</child>
            <parent>Body_RWP</parent>
            <axis>
                <xyz>-1 6.27055e-06 -2.59735e-06</xyz>
                <limit>
                    <lower>-3.14</lower>
                    <upper>3.14</upper>
                </limit>
                <dynamics />
            </axis>
        </joint>
        <link name="rightRingMedial">
            <pose>0.0031586 -0.253516 -0.408838 1.5708 0.785398 -1.5708</pose>
            <inertial>
                <pose>0.0165 0 0 0 -0 0</pose>
                <mass>0.048</mass>
                <inertia>
                    <ixx>1.152e-06</ixx>
                    <ixy>0</ixy>
                    <ixz>0</ixz>
                    <iyy>2.59e-06</iyy>
                    <iyz>3.42975e-15</iyz>
                    <izz>2.718e-06</izz>
                </inertia>
            </inertial>
            <collision name="rightRingMedial_collision">
                <pose>0 0 0 0 -0 0</pose>
                <geometry>
                    <mesh>
                        <scale>1 1 1</scale>
                        <uri>model://huboplus/dae/rightRingMedial_vis.dae</uri>
                    </mesh>
                </geometry>
            </collision>
            <visual name="rightRingMedial_vis">
                <pose>0 0 0 0 -0 0</pose>
                <geometry>
                    <mesh>
                        <scale>1 1 1</scale>
                        <uri>model://huboplus/dae/rightRingMedial_vis.dae</uri>
                    </mesh>
                </geometry>
            </visual>
        </link>
        <joint type="revolute" name="Knuckle236">
            <child>rightRingMedial</child>
            <parent>rightRingProximal</parent>
            <axis>
                <xyz>1 -6.27055e-06 2.59735e-06</xyz>
                <limit>
                    <lower>-3.14</lower>
                    <upper>3.14</upper>
                </limit>
                <dynamics />
            </axis>
        </joint>
        <link name="rightRingDistal">
            <pose>0.00315854 -0.269072 -0.424394 1.5708 0.785398 -1.5708</pose>
            <inertial>
                <pose>0.015 0 0 0 -0 0</pose>
                <mass>0.08</mass>
                <inertia>
                    <ixx>1.92e-06</ixx>
                    <ixy>0</ixy>
                    <ixz>0</ixz>
                    <iyy>3.82667e-06</iyy>
                    <iyz>5.71624e-15</iyz>
                    <izz>4.04e-06</izz>
                </inertia>
            </inertial>
            <collision name="rightRingDistal_collision">
                <pose>0 0 0 0 -0 0</pose>
                <geometry>
                    <mesh>
                        <scale>1 1 1</scale>
                        <uri>model://huboplus/dae/rightRingDistal_vis.dae</uri>
                    </mesh>
                </geometry>
            </collision>
            <visual name="rightRingDistal_vis">
                <pose>0 0 0 0 -0 0</pose>
                <geometry>
                    <mesh>
                        <scale>1 1 1</scale>
                        <uri>model://huboplus/dae/rightRingDistal_vis.dae</uri>
                    </mesh>
                </geometry>
            </visual>
        </link>
        <joint type="revolute" name="Knuckle337">
            <child>rightRingDistal</child>
            <parent>rightRingMedial</parent>
            <axis>
                <xyz>1 -6.27055e-06 2.59735e-06</xyz>
                <limit>
                    <lower>-3.14</lower>
                    <upper>3.14</upper>
                </limit>
                <dynamics />
            </axis>
        </joint>
        <link name="rightThumbProximal">
            <pose>0.0331587 -0.202948 -0.358279 1.5708 -0.785398 1.5708</pose>
            <inertial>
                <pose>0.024 0 0 0 -0 0</pose>
                <mass>0.096</mass>
                <inertia>
                    <ixx>2.304e-06</ixx>
                    <ixy>0</ixy>
                    <ixz>0</ixz>
                    <iyy>8.96e-06</iyy>
                    <iyz>6.85949e-15</iyz>
                    <izz>9.216e-06</izz>
                </inertia>
            </inertial>
            <collision name="rightThumbProximal_collision">
                <pose>0 0 0 0 -0 0</pose>
                <geometry>
                    <mesh>
                        <scale>1 1 1</scale>
                        <uri>model://huboplus/dae/rightThumbProximal_vis.dae</uri>
                    </mesh>
                </geometry>
            </collision>
            <visual name="rightThumbProximal_vis">
                <pose>0 0 0 0 -0 0</pose>
                <geometry>
                    <mesh>
                        <scale>1 1 1</scale>
                        <uri>model://huboplus/dae/rightThumbProximal_vis.dae</uri>
                    </mesh>
                </geometry>
            </visual>
        </link>
        <joint type="revolute" name="rightThumbKnuckle1">
            <child>rightThumbProximal</child>
            <parent>Body_RWP</parent>
            <axis>
                <xyz>1 6.27055e-06 -2.59735e-06</xyz>
                <limit>
                    <lower>-3.14</lower>
                    <upper>3.14</upper>
                </limit>
                <dynamics />
            </axis>
        </joint>
        <link name="rightThumbMedial">
            <pose>0.0331586 -0.18032 -0.335652 1.5708 -0.785398 1.5708</pose>
            <inertial>
                <pose>0.0165 0 0 0 -0 0</pose>
                <mass>0.048</mass>
                <inertia>
                    <ixx>1.152e-06</ixx>
                    <ixy>0</ixy>
                    <ixz>0</ixz>
                    <iyy>2.59e-06</iyy>
                    <iyz>3.42975e-15</iyz>
                    <izz>2.718e-06</izz>
                </inertia>
            </inertial>
            <collision name="rightThumbMedial_collision">
                <pose>0 0 0 0 -0 0</pose>
                <geometry>
                    <mesh>
                        <scale>1 1 1</scale>
                        <uri>model://huboplus/dae/rightThumbMedial_vis.dae</uri>
                    </mesh>
                </geometry>
            </collision>
            <visual name="rightThumbMedial_vis">
                <pose>0 0 0 0 -0 0</pose>
                <geometry>
                    <mesh>
                        <scale>1 1 1</scale>
                        <uri>model://huboplus/dae/rightThumbMedial_vis.dae</uri>
                    </mesh>
                </geometry>
            </visual>
        </link>
        <joint type="revolute" name="Knuckle230">
            <child>rightThumbMedial</child>
            <parent>rightThumbProximal</parent>
            <axis>
                <xyz>-1 -6.27055e-06 2.59735e-06</xyz>
                <limit>
                    <lower>-3.14</lower>
                    <upper>3.14</upper>
                </limit>
                <dynamics />
            </axis>
        </joint>
        <link name="rightThumbDistal">
            <pose>0.0331586 -0.164764 -0.320096 1.5708 -0.785398 1.5708</pose>
            <inertial>
                <pose>0.015 0 0 0 -0 0</pose>
                <mass>0.08</mass>
                <inertia>
                    <ixx>1.92e-06</ixx>
                    <ixy>0</ixy>
                    <ixz>0</ixz>
                    <iyy>3.82667e-06</iyy>
                    <iyz>5.71624e-15</iyz>
                    <izz>4.04e-06</izz>
                </inertia>
            </inertial>
            <collision name="rightThumbDistal_collision">
                <pose>0 0 0 0 -0 0</pose>
                <geometry>
                    <mesh>
                        <scale>1 1 1</scale>
                        <uri>model://huboplus/dae/rightThumbDistal_vis.dae</uri>
                    </mesh>
                </geometry>
            </collision>
            <visual name="rightThumbDistal_vis">
                <pose>0 0 0 0 -0 0</pose>
                <geometry>
                    <mesh>
                        <scale>1 1 1</scale>
                        <uri>model://huboplus/dae/rightThumbDistal_vis.dae</uri>
                    </mesh>
                </geometry>
            </visual>
        </link>
        <joint type="revolute" name="Knuckle331">
            <child>rightThumbDistal</child>
            <parent>rightThumbMedial</parent>
            <axis>
                <xyz>-1 -6.27055e-06 2.59735e-06</xyz>
                <limit>
                    <lower>-3.14</lower>
                    <upper>3.14</upper>
                </limit>
                <dynamics />
            </axis>
        </joint>
    </model>
</sdf>
