<sdf version="1.3">
    <model name="huboplus_lowerBody">
        <link name="Body_Hip">
            <pose>0.0122662 0.00245974 -0.15262 0 -0 0</pose>
            <inertial>
                <pose>-0.0138504 7.80652e-06 -0.0354613 0 -0 0</pose>
                <mass>3.41719</mass>
                <inertia>
                    <ixx>0.0180349</ixx>
                    <ixy>3.17531e-05</ixy>
                    <ixz>-0.000513489</ixz>
                    <iyy>0.00912382</iyy>
                    <iyz>-6.90617e-05</iyz>
                    <izz>0.0220514</izz>
                </inertia>
            </inertial>
            <collision name="Body_Hip_collision">
                <pose>0 0 0 0 -0 0</pose>
                <geometry>
                    <mesh>
                        <scale>1 1 1</scale>
                        <uri>model://huboplus/dae/Body_Hip_col.dae</uri>
                    </mesh>
                </geometry>
            </collision>
            <visual name="Body_Hip_vis">
                <pose>0 0 0 0 -0 0</pose>
                <geometry>
                    <mesh>
                        <scale>1 1 1</scale>
                        <uri>model://huboplus/dae/Body_Hip_vis.dae</uri>
                    </mesh>
                </geometry>
            </visual>
        </link>
        <link name="Body_LHY">
            <pose>0.0123913 0.0909752 -0.229089 0 -0 0</pose>
            <inertial>
                <pose>0.0347065 3.748e-05 -0.0726153 0 -0 0</pose>
                <mass>0.826125</mass>
                <inertia>
                    <ixx>0.00151818</ixx>
                    <ixy>2.13586e-06</ixy>
                    <ixz>0.000434128</ixz>
                    <iyy>0.00286333</iyy>
                    <iyz>-1.57525e-07</iyz>
                    <izz>0.00211437</izz>
                </inertia>
            </inertial>
            <collision name="Body_LHY_collision">
                <pose>0 0 0 0 -0 0</pose>
                <geometry>
                    <mesh>
                        <scale>1 1 1</scale>
                        <uri>model://huboplus/dae/Body_LHY_col.dae</uri>
                    </mesh>
                </geometry>
            </collision>
            <visual name="Body_LHY_vis">
                <pose>0 0 0 0 -0 0</pose>
                <geometry>
                    <mesh>
                        <scale>1 1 1</scale>
                        <uri>model://huboplus/dae/Body_LHY_vis.dae</uri>
                    </mesh>
                </geometry>
            </visual>
        </link>
        <joint type="revolute" name="LHY">
            <child>Body_LHY</child>
            <parent>Body_Hip</parent>
            <axis>
                <xyz>0 0 1</xyz>
                <limit>
                    <lower>-1.5708</lower>
                    <upper>1.5708</upper>
                </limit>
                <dynamics />
            </axis>
        </joint>
        <link name="Body_LHR">
            <pose>0.0643914 0.0909767 -0.320093 0 -0 0</pose>
            <inertial>
                <pose>-0.0497479 0.0125311 -0.0156437 0 -0 0</pose>
                <mass>1.93266</mass>
                <inertia>
                    <ixx>0.00403487</ixx>
                    <ixy>7.9452e-05</ixy>
                    <ixz>-0.000125343</ixz>
                    <iyy>0.00332707</iyy>
                    <iyz>-0.000551964</iyz>
                    <izz>0.00317173</izz>
                </inertia>
            </inertial>
            <collision name="Body_LHR_collision">
                <pose>0 0 0 0 -0 0</pose>
                <geometry>
                    <mesh>
                        <scale>1 1 1</scale>
                        <uri>model://huboplus/dae/Body_LHR_col.dae</uri>
                    </mesh>
                </geometry>
            </collision>
            <visual name="Body_LHR_vis">
                <pose>0 0 0 0 -0 0</pose>
                <geometry>
                    <mesh>
                        <scale>1 1 1</scale>
                        <uri>model://huboplus/dae/Body_LHR_vis.dae</uri>
                    </mesh>
                </geometry>
            </visual>
        </link>
        <joint type="revolute" name="LHR">
            <child>Body_LHR</child>
            <parent>Body_LHY</parent>
            <axis>
                <xyz>1 0 0</xyz>
                <limit>
                    <lower>-0.488692</lower>
                    <upper>0.488692</upper>
                </limit>
                <dynamics />
            </axis>
        </joint>
        <link name="Body_LHP">
            <pose>0.011484 0.156552 -0.319993 0 -0 0</pose>
            <inertial>
                <pose>0.0195049 -0.0595775 -0.175202 0 -0 0</pose>
                <mass>2.8201</mass>
                <inertia>
                    <ixx>0.0295102</ixx>
                    <ixy>0.000184399</ixy>
                    <ixz>-0.000370291</ixz>
                    <iyy>0.0273771</iyy>
                    <iyz>0.00065658</iyz>
                    <izz>0.00838035</izz>
                </inertia>
            </inertial>
            <collision name="Body_LHP_collision">
                <pose>0 0 0 0 -0 0</pose>
                <geometry>
                    <mesh>
                        <scale>1 1 1</scale>
                        <uri>model://huboplus/dae/Body_LHP_col.dae</uri>
                    </mesh>
                </geometry>
            </collision>
            <visual name="Body_LHP_vis">
                <pose>0 0 0 0 -0 0</pose>
                <geometry>
                    <mesh>
                        <scale>1 1 1</scale>
                        <uri>model://huboplus/dae/Body_LHP_vis.dae</uri>
                    </mesh>
                </geometry>
            </visual>
        </link>
        <joint type="revolute" name="LHP">
            <child>Body_LHP</child>
            <parent>Body_LHR</parent>
            <axis>
                <xyz>0 1 0</xyz>
                <limit>
                    <lower>-1.48353</lower>
                    <upper>1.6057</upper>
                </limit>
                <dynamics />
            </axis>
        </joint>
        <link name="Body_LKP">
            <pose>0.0122504 0.11205 -0.6 0 -0 0</pose>
            <inertial>
                <pose>0.0128254 -0.00727567 -0.171431 0 -0 0</pose>
                <mass>1.80912</mass>
                <inertia>
                    <ixx>0.0232156</ixx>
                    <ixy>0.000251648</ixy>
                    <ixz>-0.00129343</ixz>
                    <iyy>0.0208342</iyy>
                    <iyz>0.00278068</iyz>
                    <izz>0.0059204</izz>
                </inertia>
            </inertial>
            <collision name="Body_LKP_collision">
                <pose>0 0 0 0 -0 0</pose>
                <geometry>
                    <mesh>
                        <scale>1 1 1</scale>
                        <uri>model://huboplus/dae/Body_LKP_col.dae</uri>
                    </mesh>
                </geometry>
            </collision>
            <visual name="Body_LKP_vis">
                <pose>0 0 0 0 -0 0</pose>
                <geometry>
                    <mesh>
                        <scale>1 1 1</scale>
                        <uri>model://huboplus/dae/Body_LKP_vis.dae</uri>
                    </mesh>
                </geometry>
            </visual>
        </link>
        <joint type="revolute" name="LKP">
            <child>Body_LKP</child>
            <parent>Body_LHP</parent>
            <axis>
                <xyz>0 1 0</xyz>
                <limit>
                    <lower>-0.0698132</lower>
                    <upper>2.60054</upper>
                </limit>
                <dynamics />
            </axis>
        </joint>
        <link name="Body_LAP">
            <pose>0.0122576 0.136806 -0.879942 0 -0 0</pose>
            <inertial>
                <pose>0.0198702 -0.0459693 0.0115069 0 -0 0</pose>
                <mass>1.63501</mass>
                <inertia>
                    <ixx>0.00231659</ixx>
                    <ixy>1.87402e-05</ixy>
                    <ixz>0.000369899</ixz>
                    <iyy>0.00330411</iyy>
                    <iyz>6.38153e-05</iyz>
                    <izz>0.00279495</izz>
                </inertia>
            </inertial>
            <collision name="Body_LAP_collision">
					<!-- See if this helps -->
          <surface>
            <friction>
              <ode>
                <mu>0.5</mu>
                <mu2>0.5</mu2>
              </ode>
            </friction>
					</surface>	
					<!-- -->	
                <pose>0 0 0 0 -0 0</pose>
                <geometry>
                    <mesh>
                        <scale>1 1 1</scale>
                        <uri>model://huboplus/dae/Body_LAP_col.dae</uri>
                    </mesh>
                </geometry>
            </collision>
            <visual name="Body_LAP_vis">
                <pose>0 0 0 0 -0 0</pose>
                <geometry>
                    <mesh>
                        <scale>1 1 1</scale>
                        <uri>model://huboplus/dae/Body_LAP_vis.dae</uri>
                    </mesh>
                </geometry>
            </visual>
        </link>
        <joint type="revolute" name="LAP">
            <child>Body_LAP</child>
            <parent>Body_LKP</parent>
            <axis>
                <xyz>0 1 0</xyz>
                <limit>
                    <lower>-1.29154</lower>
                    <upper>1.69297</upper>
                </limit>
                <dynamics />
            </axis>
        </joint>
        <link name="Body_LAR">
            <pose>0.0834363 0.0902053 -0.879942 0 -0 0</pose>
            <inertial>
                <pose>-0.0515094 0.00216398 -0.0693881 0 -0 0</pose>
                <mass>1.20318</mass>
                <inertia>
                    <ixx>0.00295183</ixx>
                    <ixy>3.23211e-05</ixy>
                    <ixz>0.000141769</ixz>
                    <iyy>0.00524792</iyy>
                    <iyz>5.95404e-05</iyz>
                    <izz>0.00516817</izz>
                </inertia>
            </inertial>
            <collision name="Body_LAR_collision">
                <pose>0 0 0 0 -0 0</pose>
                <geometry>
                    <mesh>
                        <scale>1 1 1</scale>
                        <uri>model://huboplus/dae/Body_LAR_col.dae</uri>
                    </mesh>
                </geometry>
            </collision>
            <visual name="Body_LAR_vis">
                <pose>0 0 0 0 -0 0</pose>
                <geometry>
                    <mesh>
                        <scale>1 1 1</scale>
                        <uri>model://huboplus/dae/Body_LAR_vis.dae</uri>
                    </mesh>
                </geometry>
            </visual>
        </link>
        <joint type="revolute" name="LAR">
            <child>Body_LAR</child>
            <parent>Body_LAP</parent>
            <axis>
                <xyz>1 0 0</xyz>
                <limit>
                    <lower>-0.191986</lower>
                    <upper>0.191986</upper>
                </limit>
                <dynamics />
            </axis>
        </joint>
        <link name="Body_RHY">
            <pose>0.0123913 -0.0860402 -0.229089 0 -0 0</pose>
            <inertial>
                <pose>0.0347065 -3.748e-05 -0.0726153 0 -0 0</pose>
                <mass>0.826125</mass>
                <inertia>
                    <ixx>0.00151818</ixx>
                    <ixy>-2.13586e-06</ixy>
                    <ixz>0.000434128</ixz>
                    <iyy>0.00286333</iyy>
                    <iyz>1.57525e-07</iyz>
                    <izz>0.00211437</izz>
                </inertia>
            </inertial>
            <collision name="Body_RHY_collision">
                <pose>0 0 0 0 -0 0</pose>
                <geometry>
                    <mesh>
                        <scale>1 1 1</scale>
                        <uri>model://huboplus/dae/Body_RHY_col.dae</uri>
                    </mesh>
                </geometry>
            </collision>
            <visual name="Body_RHY_vis">
                <pose>0 0 0 0 -0 0</pose>
                <geometry>
                    <mesh>
                        <scale>1 1 1</scale>
                        <uri>model://huboplus/dae/Body_RHY_vis.dae</uri>
                    </mesh>
                </geometry>
            </visual>
        </link>
        <joint type="revolute" name="RHY">
            <child>Body_RHY</child>
            <parent>Body_Hip</parent>
            <axis>
                <xyz>0 0 1</xyz>
                <limit>
                    <lower>-1.5708</lower>
                    <upper>1.5708</upper>
                </limit>
                <dynamics />
            </axis>
        </joint>
        <link name="Body_RHR">
            <pose>0.0643914 -0.0859667 -0.320093 0 -0 0</pose>
            <inertial>
                <pose>-0.0497479 -0.0125311 -0.0156437 0 -0 0</pose>
                <mass>1.93266</mass>
                <inertia>
                    <ixx>0.00403487</ixx>
                    <ixy>-7.9452e-05</ixy>
                    <ixz>-0.000125343</ixz>
                    <iyy>0.00332707</iyy>
                    <iyz>0.000551964</iyz>
                    <izz>0.00317173</izz>
                </inertia>
            </inertial>
            <collision name="Body_RHR_collision">
                <pose>0 0 0 0 -0 0</pose>
                <geometry>
                    <mesh>
                        <scale>1 1 1</scale>
                        <uri>model://huboplus/dae/Body_RHR_col.dae</uri>
                    </mesh>
                </geometry>
            </collision>
            <visual name="Body_RHR_vis">
                <pose>0 0 0 0 -0 0</pose>
                <geometry>
                    <mesh>
                        <scale>1 1 1</scale>
                        <uri>model://huboplus/dae/Body_RHR_vis.dae</uri>
                    </mesh>
                </geometry>
            </visual>
        </link>
        <joint type="revolute" name="RHR">
            <child>Body_RHR</child>
            <parent>Body_RHY</parent>
            <axis>
                <xyz>1 0 0</xyz>
                <limit>
                    <lower>-0.488692</lower>
                    <upper>0.488692</upper>
                </limit>
                <dynamics />
            </axis>
        </joint>
        <link name="Body_RHP">
            <pose>0.011484 -0.151542 -0.319993 0 -0 0</pose>
            <inertial>
                <pose>0.0195049 0.0595775 -0.175202 0 -0 0</pose>
                <mass>2.8201</mass>
                <inertia>
                    <ixx>0.0295102</ixx>
                    <ixy>-0.000184399</ixy>
                    <ixz>-0.000370291</ixz>
                    <iyy>0.0273771</iyy>
                    <iyz>-0.00065658</iyz>
                    <izz>0.00838035</izz>
                </inertia>
            </inertial>
            <collision name="Body_RHP_collision">
                <pose>0 0 0 0 -0 0</pose>
                <geometry>
                    <mesh>
                        <scale>1 1 1</scale>
                        <uri>model://huboplus/dae/Body_RHP_col.dae</uri>
                    </mesh>
                </geometry>
            </collision>
            <visual name="Body_RHP_vis">
                <pose>0 0 0 0 -0 0</pose>
                <geometry>
                    <mesh>
                        <scale>1 1 1</scale>
                        <uri>model://huboplus/dae/Body_RHP_vis.dae</uri>
                    </mesh>
                </geometry>
            </visual>
        </link>
        <joint type="revolute" name="RHP">
            <child>Body_RHP</child>
            <parent>Body_RHR</parent>
            <axis>
                <xyz>0 1 0</xyz>
                <limit>
                    <lower>-1.48353</lower>
                    <upper>1.6057</upper>
                </limit>
                <dynamics />
            </axis>
        </joint>
        <link name="Body_RKP">
            <pose>0.0122504 -0.10704 -0.6 0 -0 0</pose>
            <inertial>
                <pose>0.0128254 0.00727567 -0.171431 0 -0 0</pose>
                <mass>1.80912</mass>
                <inertia>
                    <ixx>0.0232156</ixx>
                    <ixy>-0.000251648</ixy>
                    <ixz>-0.00129343</ixz>
                    <iyy>0.0208342</iyy>
                    <iyz>-0.00278068</iyz>
                    <izz>0.0059204</izz>
                </inertia>
            </inertial>
            <collision name="Body_RKP_collision">
                <pose>0 0 0 0 -0 0</pose>
                <geometry>
                    <mesh>
                        <scale>1 1 1</scale>
                        <uri>model://huboplus/dae/Body_RKP_col.dae</uri>
                    </mesh>
                </geometry>
            </collision>
            <visual name="Body_RKP_vis">
                <pose>0 0 0 0 -0 0</pose>
                <geometry>
                    <mesh>
                        <scale>1 1 1</scale>
                        <uri>model://huboplus/dae/Body_RKP_vis.dae</uri>
                    </mesh>
                </geometry>
            </visual>
        </link>
        <joint type="revolute" name="RKP">
            <child>Body_RKP</child>
            <parent>Body_RHP</parent>
            <axis>
                <xyz>0 1 0</xyz>
                <limit>
                    <lower>-0.0698132</lower>
                    <upper>2.60054</upper>
                </limit>
                <dynamics />
            </axis>
        </joint>
        <link name="Body_RAP">
            <pose>0.0122576 -0.131796 -0.879942 0 -0 0</pose>
            <inertial>
                <pose>0.0198702 0.0459693 0.0115069 0 -0 0</pose>
                <mass>1.63501</mass>
                <inertia>
                    <ixx>0.00231659</ixx>
                    <ixy>-1.87402e-05</ixy>
                    <ixz>0.000369899</ixz>
                    <iyy>0.00330411</iyy>
                    <iyz>-6.38153e-05</iyz>
                    <izz>0.00279495</izz>
                </inertia>
            </inertial>
            <collision name="Body_RAP_collision">
                <pose>0 0 0 0 -0 0</pose>
                <geometry>
                    <mesh>
                        <scale>1 1 1</scale>
                        <uri>model://huboplus/dae/Body_RAP_col.dae</uri>
                    </mesh>
                </geometry>
            </collision>
            <visual name="Body_RAP_vis">
                <pose>0 0 0 0 -0 0</pose>
                <geometry>
                    <mesh>
                        <scale>1 1 1</scale>
                        <uri>model://huboplus/dae/Body_RAP_vis.dae</uri>
                    </mesh>
                </geometry>
            </visual>
        </link>
        <joint type="revolute" name="RAP">
            <child>Body_RAP</child>
            <parent>Body_RKP</parent>
            <axis>
                <xyz>0 1 0</xyz>
                <limit>
                    <lower>-1.29154</lower>
                    <upper>1.69297</upper>
                </limit>
                <dynamics />
            </axis>
        </joint>
        <link name="Body_RAR">
            <pose>0.0834363 -0.0851953 -0.879942 0 -0 0</pose>
            <inertial>
                <pose>-0.0515094 -0.00216398 -0.0693881 0 -0 0</pose>
                <mass>1.20318</mass>
                <inertia>
                    <ixx>0.00295183</ixx>
                    <ixy>-3.23211e-05</ixy>
                    <ixz>0.000141769</ixz>
                    <iyy>0.00524792</iyy>
                    <iyz>-5.95404e-05</iyz>
                    <izz>0.00516817</izz>
                </inertia>
            </inertial>
            <collision name="Body_RAR_collision">
                <pose>0 0 0 0 -0 0</pose>
                <geometry>
                    <mesh>
                        <scale>1 1 1</scale>
                        <uri>model://huboplus/dae/Body_RAR_col.dae</uri>
                    </mesh>
                </geometry>
            </collision>
            <visual name="Body_RAR_vis">
                <pose>0 0 0 0 -0 0</pose>
                <geometry>
                    <mesh>
                        <scale>1 1 1</scale>
                        <uri>model://huboplus/dae/Body_RAR_vis.dae</uri>
                    </mesh>
                </geometry>
            </visual>
        </link>
        <joint type="revolute" name="RAR">
            <child>Body_RAR</child>
            <parent>Body_RAP</parent>
            <axis>
                <xyz>1 0 0</xyz>
                <limit>
                    <lower>-0.191986</lower>
                    <upper>0.191986</upper>
                </limit>
                <dynamics />
            </axis>
        </joint>
    </model>
</sdf>
