<?xml version="1.0"?>
<sdf version="1.3">
    <world name="default">
        <include>
          <uri>model://ground_plane</uri>
        </include>

        <include>
          <uri>model://sun</uri>
        </include>

        <model name="box">
            <link name="base_link">
                <pose>0.000000 0.000000 0.500000 0.000000 -0.000000 0.000000</pose>
                <collision name="collision">
                    <geometry>
                        <box>
                            <size>1.000000 1.000000 1.000000</size>
                        </box>
                    </geometry>
                </collision>
                <visual name="visual">
                    <geometry>
                        <box>
                            <size>1.000000 1.000000 1.000000</size>
                        </box>
                    </geometry>
                </visual>
            </link>
            <joint name="my_joint" type="prismatic">
                <parent>world</parent>
                <child>base_link</child>
                <axis>
                    <xyz>0.000000 0.000000 1.000000</xyz>
                </axis>
            </joint>
            <plugin name="pid_joints" filename="libpid_joints.so" />
        </model>
    </world>
</sdf>
